2022-12-12 02:41:06.361393: I tensorflow/core/util/util.cc:169] oneDNN custom operations are on. You may see slightly different numerical results due to floating-point round-off errors from different computation orders. To turn them off, set the environment variable `TF_ENABLE_ONEDNN_OPTS=0`.
2022-12-12 02:41:14.072212: I tensorflow/core/platform/cpu_feature_guard.cc:194] This TensorFlow binary is optimized with oneAPI Deep Neural Network Library (oneDNN) to use the following CPU instructions in performance-critical operations:  SSE3 SSE4.1 SSE4.2 AVX
To enable them in other operations, rebuild TensorFlow with the appropriate compiler flags.
2022-12-12 02:41:14.126117: I tensorflow/core/platform/cpu_feature_guard.cc:194] This TensorFlow binary is optimized with oneAPI Deep Neural Network Library (oneDNN) to use the following CPU instructions in performance-critical operations:  SSE3 SSE4.1 SSE4.2 AVX
To enable them in other operations, rebuild TensorFlow with the appropriate compiler flags.
2022-12-12 02:41:14.178751: I tensorflow/core/platform/cpu_feature_guard.cc:194] This TensorFlow binary is optimized with oneAPI Deep Neural Network Library (oneDNN) to use the following CPU instructions in performance-critical operations:  SSE3 SSE4.1 SSE4.2 AVX
To enable them in other operations, rebuild TensorFlow with the appropriate compiler flags.
2022-12-12 02:41:14.246172: I tensorflow/core/platform/cpu_feature_guard.cc:194] This TensorFlow binary is optimized with oneAPI Deep Neural Network Library (oneDNN) to use the following CPU instructions in performance-critical operations:  SSE3 SSE4.1 SSE4.2 AVX
To enable them in other operations, rebuild TensorFlow with the appropriate compiler flags.
2022-12-12 02:41:14.338386: I tensorflow/core/platform/cpu_feature_guard.cc:194] This TensorFlow binary is optimized with oneAPI Deep Neural Network Library (oneDNN) to use the following CPU instructions in performance-critical operations:  SSE3 SSE4.1 SSE4.2 AVX
To enable them in other operations, rebuild TensorFlow with the appropriate compiler flags.
2022-12-12 02:41:14.354988: I tensorflow/core/platform/cpu_feature_guard.cc:194] This TensorFlow binary is optimized with oneAPI Deep Neural Network Library (oneDNN) to use the following CPU instructions in performance-critical operations:  SSE3 SSE4.1 SSE4.2 AVX
To enable them in other operations, rebuild TensorFlow with the appropriate compiler flags.
2022-12-12 02:41:14.402676: I tensorflow/core/platform/cpu_feature_guard.cc:194] This TensorFlow binary is optimized with oneAPI Deep Neural Network Library (oneDNN) to use the following CPU instructions in performance-critical operations:  SSE3 SSE4.1 SSE4.2 AVX
To enable them in other operations, rebuild TensorFlow with the appropriate compiler flags.
2022-12-12 02:41:14.415838: I tensorflow/core/platform/cpu_feature_guard.cc:194] This TensorFlow binary is optimized with oneAPI Deep Neural Network Library (oneDNN) to use the following CPU instructions in performance-critical operations:  SSE3 SSE4.1 SSE4.2 AVX
To enable them in other operations, rebuild TensorFlow with the appropriate compiler flags.
2022-12-12 02:41:15.329893: W tensorflow/core/common_runtime/gpu/gpu_bfc_allocator.cc:42] Overriding orig_value setting because the TF_FORCE_GPU_ALLOW_GROWTH environment variable is set. Original config value was 0.
2022-12-12 02:41:15.329963: I tensorflow/core/common_runtime/gpu/gpu_device.cc:1532] Created device /job:localhost/replica:0/task:0/device:GPU:0 with 78724 MB memory:  -> device: 1, name: NVIDIA A100-SXM4-80GB, pci bus id: 0000:25:00.0, compute capability: 8.0
2022-12-12 02:41:15.343973: I tensorflow/core/common_runtime/gpu/gpu_device.cc:1532] Created device /job:worker/replica:0/task:1/device:GPU:0 with 78724 MB memory:  -> device: 1, name: NVIDIA A100-SXM4-80GB, pci bus id: 0000:25:00.0, compute capability: 8.0
2022-12-12 02:41:15.353926: W tensorflow/core/common_runtime/gpu/gpu_bfc_allocator.cc:42] Overriding orig_value setting because the TF_FORCE_GPU_ALLOW_GROWTH environment variable is set. Original config value was 0.
2022-12-12 02:41:15.353985: I tensorflow/core/common_runtime/gpu/gpu_device.cc:1532] Created device /job:localhost/replica:0/task:0/device:GPU:0 with 78724 MB memory:  -> device: 2, name: NVIDIA A100-SXM4-80GB, pci bus id: 0000:50:00.0, compute capability: 8.0
2022-12-12 02:41:15.363618: I tensorflow/core/distributed_runtime/rpc/grpc_channel.cc:272] Initialize GrpcChannelCache for job worker -> {0 -> localhost:12340, 1 -> localhost:12341, 2 -> localhost:12342, 3 -> localhost:12343, 4 -> localhost:12344, 5 -> localhost:12345, 6 -> localhost:12346, 7 -> localhost:12347}
2022-12-12 02:41:15.363753: I tensorflow/core/distributed_runtime/rpc/grpc_channel.cc:272] Initialize GrpcChannelCache for job worker -> {0 -> localhost:12340, 1 -> localhost:12341, 2 -> localhost:12342, 3 -> localhost:12343, 4 -> localhost:12344, 5 -> localhost:12345, 6 -> localhost:12346, 7 -> localhost:12347}
2022-12-12 02:41:15.368336: I tensorflow/core/common_runtime/gpu/gpu_device.cc:1532] Created device /job:worker/replica:0/task:2/device:GPU:0 with 78724 MB memory:  -> device: 2, name: NVIDIA A100-SXM4-80GB, pci bus id: 0000:50:00.0, compute capability: 8.0
2022-12-12 02:41:15.378134: W tensorflow/core/common_runtime/gpu/gpu_bfc_allocator.cc:42] Overriding orig_value setting because the TF_FORCE_GPU_ALLOW_GROWTH environment variable is set. Original config value was 0.
2022-12-12 02:41:15.378192: I tensorflow/core/common_runtime/gpu/gpu_device.cc:1532] Created device /job:localhost/replica:0/task:0/device:GPU:0 with 78724 MB memory:  -> device: 3, name: NVIDIA A100-SXM4-80GB, pci bus id: 0000:55:00.0, compute capability: 8.0
2022-12-12 02:41:15.379943: I tensorflow/core/distributed_runtime/rpc/grpc_server_lib.cc:438] Started server with target: grpc://localhost:12341
2022-12-12 02:41:15.393329: I tensorflow/core/common_runtime/gpu/gpu_device.cc:1532] Created device /job:worker/replica:0/task:3/device:GPU:0 with 78724 MB memory:  -> device: 3, name: NVIDIA A100-SXM4-80GB, pci bus id: 0000:55:00.0, compute capability: 8.0
2022-12-12 02:41:15.407096: W tensorflow/core/common_runtime/gpu/gpu_bfc_allocator.cc:42] Overriding orig_value setting because the TF_FORCE_GPU_ALLOW_GROWTH environment variable is set. Original config value was 0.
2022-12-12 02:41:15.407158: I tensorflow/core/common_runtime/gpu/gpu_device.cc:1532] Created device /job:localhost/replica:0/task:0/device:GPU:0 with 78724 MB memory:  -> device: 5, name: NVIDIA A100-SXM4-80GB, pci bus id: 0000:93:00.0, compute capability: 8.0
2022-12-12 02:41:15.408144: W tensorflow/core/common_runtime/gpu/gpu_bfc_allocator.cc:42] Overriding orig_value setting because the TF_FORCE_GPU_ALLOW_GROWTH environment variable is set. Original config value was 0.
2022-12-12 02:41:15.408183: I tensorflow/core/common_runtime/gpu/gpu_device.cc:1532] Created device /job:localhost/replica:0/task:0/device:GPU:0 with 78724 MB memory:  -> device: 0, name: NVIDIA A100-SXM4-80GB, pci bus id: 0000:1f:00.0, compute capability: 8.0
2022-12-12 02:41:15.408393: I tensorflow/core/distributed_runtime/rpc/grpc_channel.cc:272] Initialize GrpcChannelCache for job worker -> {0 -> localhost:12340, 1 -> localhost:12341, 2 -> localhost:12342, 3 -> localhost:12343, 4 -> localhost:12344, 5 -> localhost:12345, 6 -> localhost:12346, 7 -> localhost:12347}
2022-12-12 02:41:15.408488: I tensorflow/core/distributed_runtime/rpc/grpc_channel.cc:272] Initialize GrpcChannelCache for job worker -> {0 -> localhost:12340, 1 -> localhost:12341, 2 -> localhost:12342, 3 -> localhost:12343, 4 -> localhost:12344, 5 -> localhost:12345, 6 -> localhost:12346, 7 -> localhost:12347}
2022-12-12 02:41:15.409336: I tensorflow/core/distributed_runtime/rpc/grpc_server_lib.cc:438] Started server with target: grpc://localhost:12342
2022-12-12 02:41:15.420347: W tensorflow/core/common_runtime/gpu/gpu_bfc_allocator.cc:42] Overriding orig_value setting because the TF_FORCE_GPU_ALLOW_GROWTH environment variable is set. Original config value was 0.
2022-12-12 02:41:15.420390: I tensorflow/core/common_runtime/gpu/gpu_device.cc:1532] Created device /job:localhost/replica:0/task:0/device:GPU:0 with 78724 MB memory:  -> device: 7, name: NVIDIA A100-SXM4-80GB, pci bus id: 0000:d0:00.0, compute capability: 8.0
2022-12-12 02:41:15.422722: I tensorflow/core/common_runtime/gpu/gpu_device.cc:1532] Created device /job:worker/replica:0/task:5/device:GPU:0 with 78724 MB memory:  -> device: 5, name: NVIDIA A100-SXM4-80GB, pci bus id: 0000:93:00.0, compute capability: 8.0
2022-12-12 02:41:15.423403: I tensorflow/core/common_runtime/gpu/gpu_device.cc:1532] Created device /job:worker/replica:0/task:0/device:GPU:0 with 78724 MB memory:  -> device: 0, name: NVIDIA A100-SXM4-80GB, pci bus id: 0000:1f:00.0, compute capability: 8.0
2022-12-12 02:41:15.425749: W tensorflow/core/common_runtime/gpu/gpu_bfc_allocator.cc:42] Overriding orig_value setting because the TF_FORCE_GPU_ALLOW_GROWTH environment variable is set. Original config value was 0.
2022-12-12 02:41:15.425787: I tensorflow/core/common_runtime/gpu/gpu_device.cc:1532] Created device /job:localhost/replica:0/task:0/device:GPU:0 with 78724 MB memory:  -> device: 6, name: NVIDIA A100-SXM4-80GB, pci bus id: 0000:ca:00.0, compute capability: 8.0
2022-12-12 02:41:15.432437: I tensorflow/core/distributed_runtime/rpc/grpc_channel.cc:272] Initialize GrpcChannelCache for job worker -> {0 -> localhost:12340, 1 -> localhost:12341, 2 -> localhost:12342, 3 -> localhost:12343, 4 -> localhost:12344, 5 -> localhost:12345, 6 -> localhost:12346, 7 -> localhost:12347}
2022-12-12 02:41:15.432458: W tensorflow/core/common_runtime/gpu/gpu_bfc_allocator.cc:42] Overriding orig_value setting because the TF_FORCE_GPU_ALLOW_GROWTH environment variable is set. Original config value was 0.
2022-12-12 02:41:15.432492: I tensorflow/core/common_runtime/gpu/gpu_device.cc:1532] Created device /job:localhost/replica:0/task:0/device:GPU:0 with 78724 MB memory:  -> device: 4, name: NVIDIA A100-SXM4-80GB, pci bus id: 0000:8e:00.0, compute capability: 8.0
2022-12-12 02:41:15.432541: I tensorflow/core/distributed_runtime/rpc/grpc_channel.cc:272] Initialize GrpcChannelCache for job worker -> {0 -> localhost:12340, 1 -> localhost:12341, 2 -> localhost:12342, 3 -> localhost:12343, 4 -> localhost:12344, 5 -> localhost:12345, 6 -> localhost:12346, 7 -> localhost:12347}
2022-12-12 02:41:15.433380: I tensorflow/core/distributed_runtime/rpc/grpc_server_lib.cc:438] Started server with target: grpc://localhost:12343
2022-12-12 02:41:15.435352: I tensorflow/core/common_runtime/gpu/gpu_device.cc:1532] Created device /job:worker/replica:0/task:7/device:GPU:0 with 78724 MB memory:  -> device: 7, name: NVIDIA A100-SXM4-80GB, pci bus id: 0000:d0:00.0, compute capability: 8.0
2022-12-12 02:41:15.439755: I tensorflow/core/common_runtime/gpu/gpu_device.cc:1532] Created device /job:worker/replica:0/task:6/device:GPU:0 with 78724 MB memory:  -> device: 6, name: NVIDIA A100-SXM4-80GB, pci bus id: 0000:ca:00.0, compute capability: 8.0
2022-12-12 02:41:15.444889: I tensorflow/core/distributed_runtime/rpc/grpc_channel.cc:272] Initialize GrpcChannelCache for job worker -> {0 -> localhost:12340, 1 -> localhost:12341, 2 -> localhost:12342, 3 -> localhost:12343, 4 -> localhost:12344, 5 -> localhost:12345, 6 -> localhost:12346, 7 -> localhost:12347}
2022-12-12 02:41:15.444939: I tensorflow/core/distributed_runtime/rpc/grpc_channel.cc:272] Initialize GrpcChannelCache for job worker -> {0 -> localhost:12340, 1 -> localhost:12341, 2 -> localhost:12342, 3 -> localhost:12343, 4 -> localhost:12344, 5 -> localhost:12345, 6 -> localhost:12346, 7 -> localhost:12347}
2022-12-12 02:41:15.444988: I tensorflow/core/distributed_runtime/rpc/grpc_channel.cc:272] Initialize GrpcChannelCache for job worker -> {0 -> localhost:12340, 1 -> localhost:12341, 2 -> localhost:12342, 3 -> localhost:12343, 4 -> localhost:12344, 5 -> localhost:12345, 6 -> localhost:12346, 7 -> localhost:12347}
2022-12-12 02:41:15.445024: I tensorflow/core/distributed_runtime/rpc/grpc_channel.cc:272] Initialize GrpcChannelCache for job worker -> {0 -> localhost:12340, 1 -> localhost:12341, 2 -> localhost:12342, 3 -> localhost:12343, 4 -> localhost:12344, 5 -> localhost:12345, 6 -> localhost:12346, 7 -> localhost:12347}
2022-12-12 02:41:15.446099: I tensorflow/core/distributed_runtime/rpc/grpc_server_lib.cc:438] Started server with target: grpc://localhost:12340
2022-12-12 02:41:15.446316: I tensorflow/core/distributed_runtime/rpc/grpc_server_lib.cc:438] Started server with target: grpc://localhost:12345
2022-12-12 02:41:15.446943: I tensorflow/core/common_runtime/gpu/gpu_device.cc:1532] Created device /job:worker/replica:0/task:4/device:GPU:0 with 78724 MB memory:  -> device: 4, name: NVIDIA A100-SXM4-80GB, pci bus id: 0000:8e:00.0, compute capability: 8.0
2022-12-12 02:41:15.457439: I tensorflow/core/distributed_runtime/rpc/grpc_channel.cc:272] Initialize GrpcChannelCache for job worker -> {0 -> localhost:12340, 1 -> localhost:12341, 2 -> localhost:12342, 3 -> localhost:12343, 4 -> localhost:12344, 5 -> localhost:12345, 6 -> localhost:12346, 7 -> localhost:12347}
2022-12-12 02:41:15.457538: I tensorflow/core/distributed_runtime/rpc/grpc_channel.cc:272] Initialize GrpcChannelCache for job worker -> {0 -> localhost:12340, 1 -> localhost:12341, 2 -> localhost:12342, 3 -> localhost:12343, 4 -> localhost:12344, 5 -> localhost:12345, 6 -> localhost:12346, 7 -> localhost:12347}
2022-12-12 02:41:15.458441: I tensorflow/core/distributed_runtime/rpc/grpc_server_lib.cc:438] Started server with target: grpc://localhost:12347
2022-12-12 02:41:15.461597: I tensorflow/core/distributed_runtime/rpc/grpc_channel.cc:272] Initialize GrpcChannelCache for job worker -> {0 -> localhost:12340, 1 -> localhost:12341, 2 -> localhost:12342, 3 -> localhost:12343, 4 -> localhost:12344, 5 -> localhost:12345, 6 -> localhost:12346, 7 -> localhost:12347}
2022-12-12 02:41:15.461717: I tensorflow/core/distributed_runtime/rpc/grpc_channel.cc:272] Initialize GrpcChannelCache for job worker -> {0 -> localhost:12340, 1 -> localhost:12341, 2 -> localhost:12342, 3 -> localhost:12343, 4 -> localhost:12344, 5 -> localhost:12345, 6 -> localhost:12346, 7 -> localhost:12347}
2022-12-12 02:41:15.462607: I tensorflow/core/distributed_runtime/rpc/grpc_server_lib.cc:438] Started server with target: grpc://localhost:12346
2022-12-12 02:41:15.467961: I tensorflow/core/distributed_runtime/rpc/grpc_channel.cc:272] Initialize GrpcChannelCache for job worker -> {0 -> localhost:12340, 1 -> localhost:12341, 2 -> localhost:12342, 3 -> localhost:12343, 4 -> localhost:12344, 5 -> localhost:12345, 6 -> localhost:12346, 7 -> localhost:12347}
2022-12-12 02:41:15.468049: I tensorflow/core/distributed_runtime/rpc/grpc_channel.cc:272] Initialize GrpcChannelCache for job worker -> {0 -> localhost:12340, 1 -> localhost:12341, 2 -> localhost:12342, 3 -> localhost:12343, 4 -> localhost:12344, 5 -> localhost:12345, 6 -> localhost:12346, 7 -> localhost:12347}
2022-12-12 02:41:15.468998: I tensorflow/core/distributed_runtime/rpc/grpc_server_lib.cc:438] Started server with target: grpc://localhost:12344
[HCTR][02:41:17.561][ERROR][RK0][main]: using mock embedding with 882774585 * 128 elements
[HCTR][02:41:17.566][ERROR][RK0][main]: using mock embedding with 882774585 * 128 elements
[HCTR][02:41:17.566][ERROR][RK0][main]: using mock embedding with 882774585 * 128 elements
[HCTR][02:41:17.566][ERROR][RK0][main]: using mock embedding with 882774585 * 128 elements
[HCTR][02:41:17.572][ERROR][RK0][main]: using mock embedding with 882774585 * 128 elements
[HCTR][02:41:17.572][ERROR][RK0][main]: using mock embedding with 882774585 * 128 elements
[HCTR][02:41:17.615][ERROR][RK0][main]: using mock embedding with 882774585 * 128 elements
[HCTR][02:41:17.615][ERROR][RK0][main]: using mock embedding with 882774585 * 128 elements
2022-12-12 02:41:25.465050: E tensorflow/core/common_runtime/base_collective_executor.cc:249] BaseCollectiveExecutor::StartAbort DEADLINE_EXCEEDED: Deadline Exceeded
Additional GRPC error information from remote target /job:worker/replica:0/task:0:
:{"created":"@1670812885.464906284","description":"Error received from peer ipv4:127.0.0.1:12340","file":"external/com_github_grpc_grpc/src/core/lib/surface/call.cc","file_line":1056,"grpc_message":"Deadline Exceeded","grpc_status":4}
2022-12-12 02:41:50.471399: E tensorflow/core/common_runtime/base_collective_executor.cc:249] BaseCollectiveExecutor::StartAbort DEADLINE_EXCEEDED: Deadline Exceeded
Additional GRPC error information from remote target /job:worker/replica:0/task:0:
:{"created":"@1670812910.471266244","description":"Error received from peer ipv4:127.0.0.1:12340","file":"external/com_github_grpc_grpc/src/core/lib/surface/call.cc","file_line":1056,"grpc_message":"Deadline Exceeded","grpc_status":4}
2022-12-12 02:41:50.471578: E tensorflow/core/common_runtime/base_collective_executor.cc:249] BaseCollectiveExecutor::StartAbort DEADLINE_EXCEEDED: Deadline Exceeded
Additional GRPC error information from remote target /job:worker/replica:0/task:0:
:{"created":"@1670812910.471453339","description":"Error received from peer ipv4:127.0.0.1:12340","file":"external/com_github_grpc_grpc/src/core/lib/surface/call.cc","file_line":1056,"grpc_message":"Deadline Exceeded","grpc_status":4}
2022-12-12 02:41:56.383667: E tensorflow/core/common_runtime/base_collective_executor.cc:249] BaseCollectiveExecutor::StartAbort DEADLINE_EXCEEDED: Deadline Exceeded
Additional GRPC error information from remote target /job:worker/replica:0/task:0:
:{"created":"@1670812916.383541618","description":"Error received from peer ipv4:127.0.0.1:12340","file":"external/com_github_grpc_grpc/src/core/lib/surface/call.cc","file_line":1056,"grpc_message":"Deadline Exceeded","grpc_status":4}
2022-12-12 02:42:41.415039: E tensorflow/core/common_runtime/base_collective_executor.cc:249] BaseCollectiveExecutor::StartAbort DEADLINE_EXCEEDED: Deadline Exceeded
Additional GRPC error information from remote target /job:worker/replica:0/task:0:
:{"created":"@1670812961.414904159","description":"Error received from peer ipv4:127.0.0.1:12340","file":"external/com_github_grpc_grpc/src/core/lib/surface/call.cc","file_line":1056,"grpc_message":"Deadline Exceeded","grpc_status":4}
2022-12-12 02:42:58.269919: E tensorflow/core/distributed_runtime/coordination/coordination_service.cc:730] Encountered another error while reporting to /job:worker/replica:0/task:2: DEADLINE_EXCEEDED: Deadline Exceeded
Additional GRPC error information from remote target /job:worker/replica:0/task:2:
:{"created":"@1670812896.446860645","description":"Deadline Exceeded","file":"external/com_github_grpc_grpc/src/core/ext/filters/deadline/deadline_filter.cc","file_line":69,"grpc_status":4}
2022-12-12 02:42:58.269963: E tensorflow/core/distributed_runtime/coordination/coordination_service.cc:730] Encountered another error while reporting to /job:worker/replica:0/task:5: DEADLINE_EXCEEDED: Deadline Exceeded
Additional GRPC error information from remote target /job:worker/replica:0/task:5:
:{"created":"@1670812896.446861351","description":"Deadline Exceeded","file":"external/com_github_grpc_grpc/src/core/ext/filters/deadline/deadline_filter.cc","file_line":69,"grpc_status":4}
2022-12-12 02:42:58.270013: E tensorflow/core/distributed_runtime/coordination/coordination_service.cc:730] Encountered another error while reporting to /job:worker/replica:0/task:4: DEADLINE_EXCEEDED: Deadline Exceeded
Additional GRPC error information from remote target /job:worker/replica:0/task:4:
:{"created":"@1670812896.446861812","description":"Deadline Exceeded","file":"external/com_github_grpc_grpc/src/core/ext/filters/deadline/deadline_filter.cc","file_line":69,"grpc_status":4}
2022-12-12 02:42:58.270452: E tensorflow/core/common_runtime/base_collective_executor.cc:249] BaseCollectiveExecutor::StartAbort UNAVAILABLE: Error reported from /job:worker/task:3: Task /job:worker/replica:0/task:3 heartbeat timeout. This indicates that the remote task has failed, got preempted, or crashed unexpectedly. [type.googleapis.com/tensorflow.CoordinationServiceError='\"\n\n\x06worker\x10\x03']
2022-12-12 02:42:58.270720: E tensorflow/core/common_runtime/base_collective_executor.cc:249] BaseCollectiveExecutor::StartAbort UNAVAILABLE: Error reported from /job:worker/task:3: Task /job:worker/replica:0/task:3 heartbeat timeout. This indicates that the remote task has failed, got preempted, or crashed unexpectedly. [type.googleapis.com/tensorflow.CoordinationServiceError='\"\n\n\x06worker\x10\x03']
2022-12-12 02:42:58.273476: E tensorflow/core/common_runtime/base_collective_executor.cc:249] BaseCollectiveExecutor::StartAbort UNAVAILABLE: Error reported from /job:worker/task:3: Task /job:worker/replica:0/task:3 heartbeat timeout. This indicates that the remote task has failed, got preempted, or crashed unexpectedly. [type.googleapis.com/tensorflow.CoordinationServiceError='\"\n\n\x06worker\x10\x03']
Process Process-6:
Traceback (most recent call last):
  File "/usr/lib/python3.8/multiprocessing/process.py", line 315, in _bootstrap
    self.run()
  File "/usr/lib/python3.8/multiprocessing/process.py", line 108, in run
    self._target(*self._args, **self._kwargs)
  File "../examples/inference.py", line 211, in proc_func
    embeddings_peek, inputs_peek = inference_with_saved_model(args)
  File "../examples/inference.py", line 101, in inference_with_saved_model
    model = prepare_model(args)
  File "../examples/inference.py", line 80, in prepare_model
    model = DLRMHPS("mean", args["max_vocabulary_size"] // args["gpu_num"], args["embed_vec_size"], args["slot_num"], args["dense_dim"],
  File "/hugectr_dev/study/examples/model_zoo.py", line 145, in __init__
    super(DLRMHPS, self).__init__(**kwargs)
  File "/usr/local/lib/python3.8/dist-packages/tensorflow/python/training/tracking/base.py", line 587, in _method_wrapper
    result = method(self, *args, **kwargs)
  File "/usr/local/lib/python3.8/dist-packages/keras/utils/traceback_utils.py", line 67, in error_handler
    raise e.with_traceback(filtered_tb) from None
  File "/usr/local/lib/python3.8/dist-packages/tensorflow/python/eager/execute.py", line 54, in quick_execute
    tensors = pywrap_tfe.TFE_Py_Execute(ctx._handle, device_name, op_name,
tensorflow.python.framework.errors_impl.DeadlineExceededError: Collective ops is aborted by: Deadline Exceeded
Additional GRPC error information from remote target /job:worker/replica:0/task:0:
:{"created":"@1670812910.471266244","description":"Error received from peer ipv4:127.0.0.1:12340","file":"external/com_github_grpc_grpc/src/core/lib/surface/call.cc","file_line":1056,"grpc_message":"Deadline Exceeded","grpc_status":4}
The error could be from a previous operation. Restart your program to reset. [Op:CollectiveBcastRecv]
Process Process-4:
Traceback (most recent call last):
  File "/usr/lib/python3.8/multiprocessing/process.py", line 315, in _bootstrap
    self.run()
  File "/usr/lib/python3.8/multiprocessing/process.py", line 108, in run
    self._target(*self._args, **self._kwargs)
  File "../examples/inference.py", line 211, in proc_func
    embeddings_peek, inputs_peek = inference_with_saved_model(args)
  File "../examples/inference.py", line 101, in inference_with_saved_model
    model = prepare_model(args)
  File "../examples/inference.py", line 80, in prepare_model
    model = DLRMHPS("mean", args["max_vocabulary_size"] // args["gpu_num"], args["embed_vec_size"], args["slot_num"], args["dense_dim"],
  File "/hugectr_dev/study/examples/model_zoo.py", line 145, in __init__
    super(DLRMHPS, self).__init__(**kwargs)
  File "/usr/local/lib/python3.8/dist-packages/tensorflow/python/training/tracking/base.py", line 587, in _method_wrapper
    result = method(self, *args, **kwargs)
  File "/usr/local/lib/python3.8/dist-packages/keras/utils/traceback_utils.py", line 67, in error_handler
    raise e.with_traceback(filtered_tb) from None
  File "/usr/local/lib/python3.8/dist-packages/tensorflow/python/eager/execute.py", line 54, in quick_execute
    tensors = pywrap_tfe.TFE_Py_Execute(ctx._handle, device_name, op_name,
tensorflow.python.framework.errors_impl.DeadlineExceededError: Collective ops is aborted by: Deadline Exceeded
Additional GRPC error information from remote target /job:worker/replica:0/task:0:
:{"created":"@1670812885.464906284","description":"Error received from peer ipv4:127.0.0.1:12340","file":"external/com_github_grpc_grpc/src/core/lib/surface/call.cc","file_line":1056,"grpc_message":"Deadline Exceeded","grpc_status":4}
The error could be from a previous operation. Restart your program to reset. [Op:CollectiveBcastRecv]
Process Process-3:
Traceback (most recent call last):
  File "/usr/lib/python3.8/multiprocessing/process.py", line 315, in _bootstrap
    self.run()
  File "/usr/lib/python3.8/multiprocessing/process.py", line 108, in run
    self._target(*self._args, **self._kwargs)
  File "../examples/inference.py", line 211, in proc_func
    embeddings_peek, inputs_peek = inference_with_saved_model(args)
  File "../examples/inference.py", line 101, in inference_with_saved_model
    model = prepare_model(args)
  File "../examples/inference.py", line 80, in prepare_model
    model = DLRMHPS("mean", args["max_vocabulary_size"] // args["gpu_num"], args["embed_vec_size"], args["slot_num"], args["dense_dim"],
  File "/hugectr_dev/study/examples/model_zoo.py", line 145, in __init__
    super(DLRMHPS, self).__init__(**kwargs)
  File "/usr/local/lib/python3.8/dist-packages/tensorflow/python/training/tracking/base.py", line 587, in _method_wrapper
    result = method(self, *args, **kwargs)
  File "/usr/local/lib/python3.8/dist-packages/keras/utils/traceback_utils.py", line 67, in error_handler
    raise e.with_traceback(filtered_tb) from None
  File "/usr/local/lib/python3.8/dist-packages/tensorflow/python/eager/execute.py", line 54, in quick_execute
    tensors = pywrap_tfe.TFE_Py_Execute(ctx._handle, device_name, op_name,
tensorflow.python.framework.errors_impl.DeadlineExceededError: Collective ops is aborted by: Deadline Exceeded
Additional GRPC error information from remote target /job:worker/replica:0/task:0:
:{"created":"@1670812961.414904159","description":"Error received from peer ipv4:127.0.0.1:12340","file":"external/com_github_grpc_grpc/src/core/lib/surface/call.cc","file_line":1056,"grpc_message":"Deadline Exceeded","grpc_status":4}
The error could be from a previous operation. Restart your program to reset. [Op:CollectiveBcastRecv]
Process Process-8:
Traceback (most recent call last):
  File "/usr/lib/python3.8/multiprocessing/process.py", line 315, in _bootstrap
    self.run()
  File "/usr/lib/python3.8/multiprocessing/process.py", line 108, in run
    self._target(*self._args, **self._kwargs)
  File "../examples/inference.py", line 211, in proc_func
    embeddings_peek, inputs_peek = inference_with_saved_model(args)
  File "../examples/inference.py", line 101, in inference_with_saved_model
    model = prepare_model(args)
  File "../examples/inference.py", line 80, in prepare_model
    model = DLRMHPS("mean", args["max_vocabulary_size"] // args["gpu_num"], args["embed_vec_size"], args["slot_num"], args["dense_dim"],
  File "/hugectr_dev/study/examples/model_zoo.py", line 145, in __init__
    super(DLRMHPS, self).__init__(**kwargs)
  File "/usr/local/lib/python3.8/dist-packages/tensorflow/python/training/tracking/base.py", line 587, in _method_wrapper
    result = method(self, *args, **kwargs)
  File "/usr/local/lib/python3.8/dist-packages/keras/utils/traceback_utils.py", line 67, in error_handler
    raise e.with_traceback(filtered_tb) from None
  File "/usr/local/lib/python3.8/dist-packages/tensorflow/python/eager/execute.py", line 54, in quick_execute
    tensors = pywrap_tfe.TFE_Py_Execute(ctx._handle, device_name, op_name,
tensorflow.python.framework.errors_impl.UnavailableError: Collective ops is aborted by: Error reported from /job:worker/task:3: Task /job:worker/replica:0/task:3 heartbeat timeout. This indicates that the remote task has failed, got preempted, or crashed unexpectedly.
The error could be from a previous operation. Restart your program to reset. [Op:CollectiveBcastRecv]
Process Process-7:
Traceback (most recent call last):
  File "/usr/lib/python3.8/multiprocessing/process.py", line 315, in _bootstrap
    self.run()
  File "/usr/lib/python3.8/multiprocessing/process.py", line 108, in run
    self._target(*self._args, **self._kwargs)
  File "../examples/inference.py", line 211, in proc_func
    embeddings_peek, inputs_peek = inference_with_saved_model(args)
  File "../examples/inference.py", line 101, in inference_with_saved_model
    model = prepare_model(args)
  File "../examples/inference.py", line 80, in prepare_model
    model = DLRMHPS("mean", args["max_vocabulary_size"] // args["gpu_num"], args["embed_vec_size"], args["slot_num"], args["dense_dim"],
  File "/hugectr_dev/study/examples/model_zoo.py", line 145, in __init__
    super(DLRMHPS, self).__init__(**kwargs)
  File "/usr/local/lib/python3.8/dist-packages/tensorflow/python/training/tracking/base.py", line 587, in _method_wrapper
    result = method(self, *args, **kwargs)
  File "/usr/local/lib/python3.8/dist-packages/keras/utils/traceback_utils.py", line 67, in error_handler
    raise e.with_traceback(filtered_tb) from None
  File "/usr/local/lib/python3.8/dist-packages/tensorflow/python/eager/execute.py", line 54, in quick_execute
    tensors = pywrap_tfe.TFE_Py_Execute(ctx._handle, device_name, op_name,
tensorflow.python.framework.errors_impl.UnavailableError: Collective ops is aborted by: Error reported from /job:worker/task:3: Task /job:worker/replica:0/task:3 heartbeat timeout. This indicates that the remote task has failed, got preempted, or crashed unexpectedly.
The error could be from a previous operation. Restart your program to reset. [Op:CollectiveBcastRecv]
Process Process-2:
Traceback (most recent call last):
  File "/usr/lib/python3.8/multiprocessing/process.py", line 315, in _bootstrap
    self.run()
  File "/usr/lib/python3.8/multiprocessing/process.py", line 108, in run
    self._target(*self._args, **self._kwargs)
  File "../examples/inference.py", line 211, in proc_func
    embeddings_peek, inputs_peek = inference_with_saved_model(args)
  File "../examples/inference.py", line 101, in inference_with_saved_model
    model = prepare_model(args)
  File "../examples/inference.py", line 80, in prepare_model
    model = DLRMHPS("mean", args["max_vocabulary_size"] // args["gpu_num"], args["embed_vec_size"], args["slot_num"], args["dense_dim"],
  File "/hugectr_dev/study/examples/model_zoo.py", line 145, in __init__
    super(DLRMHPS, self).__init__(**kwargs)
  File "/usr/local/lib/python3.8/dist-packages/tensorflow/python/training/tracking/base.py", line 587, in _method_wrapper
    result = method(self, *args, **kwargs)
  File "/usr/local/lib/python3.8/dist-packages/keras/utils/traceback_utils.py", line 67, in error_handler
    raise e.with_traceback(filtered_tb) from None
  File "/usr/local/lib/python3.8/dist-packages/tensorflow/python/eager/execute.py", line 54, in quick_execute
    tensors = pywrap_tfe.TFE_Py_Execute(ctx._handle, device_name, op_name,
tensorflow.python.framework.errors_impl.DeadlineExceededError: Collective ops is aborted by: Deadline Exceeded
Additional GRPC error information from remote target /job:worker/replica:0/task:0:
:{"created":"@1670812916.383541618","description":"Error received from peer ipv4:127.0.0.1:12340","file":"external/com_github_grpc_grpc/src/core/lib/surface/call.cc","file_line":1056,"grpc_message":"Deadline Exceeded","grpc_status":4}
The error could be from a previous operation. Restart your program to reset. [Op:CollectiveBcastRecv]
Process Process-5:
Traceback (most recent call last):
  File "/usr/lib/python3.8/multiprocessing/process.py", line 315, in _bootstrap
    self.run()
  File "/usr/lib/python3.8/multiprocessing/process.py", line 108, in run
    self._target(*self._args, **self._kwargs)
  File "../examples/inference.py", line 211, in proc_func
    embeddings_peek, inputs_peek = inference_with_saved_model(args)
  File "../examples/inference.py", line 101, in inference_with_saved_model
    model = prepare_model(args)
  File "../examples/inference.py", line 80, in prepare_model
    model = DLRMHPS("mean", args["max_vocabulary_size"] // args["gpu_num"], args["embed_vec_size"], args["slot_num"], args["dense_dim"],
  File "/hugectr_dev/study/examples/model_zoo.py", line 145, in __init__
    super(DLRMHPS, self).__init__(**kwargs)
  File "/usr/local/lib/python3.8/dist-packages/tensorflow/python/training/tracking/base.py", line 587, in _method_wrapper
    result = method(self, *args, **kwargs)
  File "/usr/local/lib/python3.8/dist-packages/keras/utils/traceback_utils.py", line 67, in error_handler
    raise e.with_traceback(filtered_tb) from None
  File "/usr/local/lib/python3.8/dist-packages/tensorflow/python/eager/execute.py", line 54, in quick_execute
    tensors = pywrap_tfe.TFE_Py_Execute(ctx._handle, device_name, op_name,
tensorflow.python.framework.errors_impl.DeadlineExceededError: Collective ops is aborted by: Deadline Exceeded
Additional GRPC error information from remote target /job:worker/replica:0/task:0:
:{"created":"@1670812910.471453339","description":"Error received from peer ipv4:127.0.0.1:12340","file":"external/com_github_grpc_grpc/src/core/lib/surface/call.cc","file_line":1056,"grpc_message":"Deadline Exceeded","grpc_status":4}
The error could be from a previous operation. Restart your program to reset. [Op:CollectiveBcastRecv]
Process Process-1:
Traceback (most recent call last):
  File "/usr/lib/python3.8/multiprocessing/process.py", line 315, in _bootstrap
    self.run()
  File "/usr/lib/python3.8/multiprocessing/process.py", line 108, in run
    self._target(*self._args, **self._kwargs)
  File "../examples/inference.py", line 211, in proc_func
    embeddings_peek, inputs_peek = inference_with_saved_model(args)
  File "../examples/inference.py", line 101, in inference_with_saved_model
    model = prepare_model(args)
  File "../examples/inference.py", line 80, in prepare_model
    model = DLRMHPS("mean", args["max_vocabulary_size"] // args["gpu_num"], args["embed_vec_size"], args["slot_num"], args["dense_dim"],
  File "/hugectr_dev/study/examples/model_zoo.py", line 145, in __init__
    super(DLRMHPS, self).__init__(**kwargs)
  File "/usr/local/lib/python3.8/dist-packages/tensorflow/python/training/tracking/base.py", line 587, in _method_wrapper
    result = method(self, *args, **kwargs)
  File "/usr/local/lib/python3.8/dist-packages/keras/utils/traceback_utils.py", line 67, in error_handler
    raise e.with_traceback(filtered_tb) from None
  File "/usr/local/lib/python3.8/dist-packages/tensorflow/python/eager/execute.py", line 54, in quick_execute
    tensors = pywrap_tfe.TFE_Py_Execute(ctx._handle, device_name, op_name,
tensorflow.python.framework.errors_impl.UnavailableError: Collective ops is aborted by: Error reported from /job:worker/task:3: Task /job:worker/replica:0/task:3 heartbeat timeout. This indicates that the remote task has failed, got preempted, or crashed unexpectedly.
The error could be from a previous operation. Restart your program to reset. [Op:CollectiveBcastSend]
