2022-12-12 03:51:43.969382: I tensorflow/core/util/util.cc:169] oneDNN custom operations are on. You may see slightly different numerical results due to floating-point round-off errors from different computation orders. To turn them off, set the environment variable `TF_ENABLE_ONEDNN_OPTS=0`.
2022-12-12 03:51:51.773135: I tensorflow/core/platform/cpu_feature_guard.cc:194] This TensorFlow binary is optimized with oneAPI Deep Neural Network Library (oneDNN) to use the following CPU instructions in performance-critical operations:  SSE3 SSE4.1 SSE4.2 AVX
To enable them in other operations, rebuild TensorFlow with the appropriate compiler flags.
2022-12-12 03:51:51.812200: I tensorflow/core/platform/cpu_feature_guard.cc:194] This TensorFlow binary is optimized with oneAPI Deep Neural Network Library (oneDNN) to use the following CPU instructions in performance-critical operations:  SSE3 SSE4.1 SSE4.2 AVX
To enable them in other operations, rebuild TensorFlow with the appropriate compiler flags.
2022-12-12 03:51:51.862775: I tensorflow/core/platform/cpu_feature_guard.cc:194] This TensorFlow binary is optimized with oneAPI Deep Neural Network Library (oneDNN) to use the following CPU instructions in performance-critical operations:  SSE3 SSE4.1 SSE4.2 AVX
To enable them in other operations, rebuild TensorFlow with the appropriate compiler flags.
2022-12-12 03:51:51.923564: I tensorflow/core/platform/cpu_feature_guard.cc:194] This TensorFlow binary is optimized with oneAPI Deep Neural Network Library (oneDNN) to use the following CPU instructions in performance-critical operations:  SSE3 SSE4.1 SSE4.2 AVX
To enable them in other operations, rebuild TensorFlow with the appropriate compiler flags.
2022-12-12 03:51:51.961671: I tensorflow/core/platform/cpu_feature_guard.cc:194] This TensorFlow binary is optimized with oneAPI Deep Neural Network Library (oneDNN) to use the following CPU instructions in performance-critical operations:  SSE3 SSE4.1 SSE4.2 AVX
To enable them in other operations, rebuild TensorFlow with the appropriate compiler flags.
2022-12-12 03:51:51.994722: I tensorflow/core/platform/cpu_feature_guard.cc:194] This TensorFlow binary is optimized with oneAPI Deep Neural Network Library (oneDNN) to use the following CPU instructions in performance-critical operations:  SSE3 SSE4.1 SSE4.2 AVX
To enable them in other operations, rebuild TensorFlow with the appropriate compiler flags.
2022-12-12 03:51:52.025865: I tensorflow/core/platform/cpu_feature_guard.cc:194] This TensorFlow binary is optimized with oneAPI Deep Neural Network Library (oneDNN) to use the following CPU instructions in performance-critical operations:  SSE3 SSE4.1 SSE4.2 AVX
To enable them in other operations, rebuild TensorFlow with the appropriate compiler flags.
2022-12-12 03:51:52.065302: I tensorflow/core/platform/cpu_feature_guard.cc:194] This TensorFlow binary is optimized with oneAPI Deep Neural Network Library (oneDNN) to use the following CPU instructions in performance-critical operations:  SSE3 SSE4.1 SSE4.2 AVX
To enable them in other operations, rebuild TensorFlow with the appropriate compiler flags.
2022-12-12 03:51:52.976162: W tensorflow/core/common_runtime/gpu/gpu_bfc_allocator.cc:42] Overriding orig_value setting because the TF_FORCE_GPU_ALLOW_GROWTH environment variable is set. Original config value was 0.
2022-12-12 03:51:52.976226: I tensorflow/core/common_runtime/gpu/gpu_device.cc:1532] Created device /job:localhost/replica:0/task:0/device:GPU:0 with 78724 MB memory:  -> device: 1, name: NVIDIA A100-SXM4-80GB, pci bus id: 0000:25:00.0, compute capability: 8.0
2022-12-12 03:51:52.991202: I tensorflow/core/common_runtime/gpu/gpu_device.cc:1532] Created device /job:worker/replica:0/task:1/device:GPU:0 with 78724 MB memory:  -> device: 1, name: NVIDIA A100-SXM4-80GB, pci bus id: 0000:25:00.0, compute capability: 8.0
2022-12-12 03:51:53.009797: W tensorflow/core/common_runtime/gpu/gpu_bfc_allocator.cc:42] Overriding orig_value setting because the TF_FORCE_GPU_ALLOW_GROWTH environment variable is set. Original config value was 0.
2022-12-12 03:51:53.009868: I tensorflow/core/common_runtime/gpu/gpu_device.cc:1532] Created device /job:localhost/replica:0/task:0/device:GPU:0 with 78724 MB memory:  -> device: 2, name: NVIDIA A100-SXM4-80GB, pci bus id: 0000:50:00.0, compute capability: 8.0
2022-12-12 03:51:53.013301: I tensorflow/core/distributed_runtime/rpc/grpc_channel.cc:272] Initialize GrpcChannelCache for job worker -> {0 -> localhost:12340, 1 -> localhost:12341, 2 -> localhost:12342, 3 -> localhost:12343, 4 -> localhost:12344, 5 -> localhost:12345, 6 -> localhost:12346, 7 -> localhost:12347}
2022-12-12 03:51:53.013433: I tensorflow/core/distributed_runtime/rpc/grpc_channel.cc:272] Initialize GrpcChannelCache for job worker -> {0 -> localhost:12340, 1 -> localhost:12341, 2 -> localhost:12342, 3 -> localhost:12343, 4 -> localhost:12344, 5 -> localhost:12345, 6 -> localhost:12346, 7 -> localhost:12347}
2022-12-12 03:51:53.024668: I tensorflow/core/common_runtime/gpu/gpu_device.cc:1532] Created device /job:worker/replica:0/task:2/device:GPU:0 with 78724 MB memory:  -> device: 2, name: NVIDIA A100-SXM4-80GB, pci bus id: 0000:50:00.0, compute capability: 8.0
2022-12-12 03:51:53.030067: I tensorflow/core/distributed_runtime/rpc/grpc_server_lib.cc:438] Started server with target: grpc://localhost:12341
2022-12-12 03:51:53.039330: W tensorflow/core/common_runtime/gpu/gpu_bfc_allocator.cc:42] Overriding orig_value setting because the TF_FORCE_GPU_ALLOW_GROWTH environment variable is set. Original config value was 0.
2022-12-12 03:51:53.039389: I tensorflow/core/common_runtime/gpu/gpu_device.cc:1532] Created device /job:localhost/replica:0/task:0/device:GPU:0 with 78724 MB memory:  -> device: 7, name: NVIDIA A100-SXM4-80GB, pci bus id: 0000:d0:00.0, compute capability: 8.0
2022-12-12 03:51:53.044513: W tensorflow/core/common_runtime/gpu/gpu_bfc_allocator.cc:42] Overriding orig_value setting because the TF_FORCE_GPU_ALLOW_GROWTH environment variable is set. Original config value was 0.
2022-12-12 03:51:53.044575: I tensorflow/core/common_runtime/gpu/gpu_device.cc:1532] Created device /job:localhost/replica:0/task:0/device:GPU:0 with 78724 MB memory:  -> device: 4, name: NVIDIA A100-SXM4-80GB, pci bus id: 0000:8e:00.0, compute capability: 8.0
2022-12-12 03:51:53.046136: W tensorflow/core/common_runtime/gpu/gpu_bfc_allocator.cc:42] Overriding orig_value setting because the TF_FORCE_GPU_ALLOW_GROWTH environment variable is set. Original config value was 0.
2022-12-12 03:51:53.046180: I tensorflow/core/common_runtime/gpu/gpu_device.cc:1532] Created device /job:localhost/replica:0/task:0/device:GPU:0 with 78724 MB memory:  -> device: 0, name: NVIDIA A100-SXM4-80GB, pci bus id: 0000:1f:00.0, compute capability: 8.0
2022-12-12 03:51:53.054926: I tensorflow/core/common_runtime/gpu/gpu_device.cc:1532] Created device /job:worker/replica:0/task:7/device:GPU:0 with 78724 MB memory:  -> device: 7, name: NVIDIA A100-SXM4-80GB, pci bus id: 0000:d0:00.0, compute capability: 8.0
2022-12-12 03:51:53.059708: I tensorflow/core/common_runtime/gpu/gpu_device.cc:1532] Created device /job:worker/replica:0/task:4/device:GPU:0 with 78724 MB memory:  -> device: 4, name: NVIDIA A100-SXM4-80GB, pci bus id: 0000:8e:00.0, compute capability: 8.0
2022-12-12 03:51:53.060643: I tensorflow/core/common_runtime/gpu/gpu_device.cc:1532] Created device /job:worker/replica:0/task:0/device:GPU:0 with 78724 MB memory:  -> device: 0, name: NVIDIA A100-SXM4-80GB, pci bus id: 0000:1f:00.0, compute capability: 8.0
2022-12-12 03:51:53.064770: W tensorflow/core/common_runtime/gpu/gpu_bfc_allocator.cc:42] Overriding orig_value setting because the TF_FORCE_GPU_ALLOW_GROWTH environment variable is set. Original config value was 0.
2022-12-12 03:51:53.064819: I tensorflow/core/common_runtime/gpu/gpu_device.cc:1532] Created device /job:localhost/replica:0/task:0/device:GPU:0 with 78724 MB memory:  -> device: 6, name: NVIDIA A100-SXM4-80GB, pci bus id: 0000:ca:00.0, compute capability: 8.0
2022-12-12 03:51:53.066421: I tensorflow/core/distributed_runtime/rpc/grpc_channel.cc:272] Initialize GrpcChannelCache for job worker -> {0 -> localhost:12340, 1 -> localhost:12341, 2 -> localhost:12342, 3 -> localhost:12343, 4 -> localhost:12344, 5 -> localhost:12345, 6 -> localhost:12346, 7 -> localhost:12347}
2022-12-12 03:51:53.066533: I tensorflow/core/distributed_runtime/rpc/grpc_channel.cc:272] Initialize GrpcChannelCache for job worker -> {0 -> localhost:12340, 1 -> localhost:12341, 2 -> localhost:12342, 3 -> localhost:12343, 4 -> localhost:12344, 5 -> localhost:12345, 6 -> localhost:12346, 7 -> localhost:12347}
2022-12-12 03:51:53.067414: I tensorflow/core/distributed_runtime/rpc/grpc_server_lib.cc:438] Started server with target: grpc://localhost:12342
2022-12-12 03:51:53.077321: I tensorflow/core/distributed_runtime/rpc/grpc_channel.cc:272] Initialize GrpcChannelCache for job worker -> {0 -> localhost:12340, 1 -> localhost:12341, 2 -> localhost:12342, 3 -> localhost:12343, 4 -> localhost:12344, 5 -> localhost:12345, 6 -> localhost:12346, 7 -> localhost:12347}
2022-12-12 03:51:53.077429: I tensorflow/core/distributed_runtime/rpc/grpc_channel.cc:272] Initialize GrpcChannelCache for job worker -> {0 -> localhost:12340, 1 -> localhost:12341, 2 -> localhost:12342, 3 -> localhost:12343, 4 -> localhost:12344, 5 -> localhost:12345, 6 -> localhost:12346, 7 -> localhost:12347}
2022-12-12 03:51:53.078277: I tensorflow/core/distributed_runtime/rpc/grpc_server_lib.cc:438] Started server with target: grpc://localhost:12347
2022-12-12 03:51:53.079973: I tensorflow/core/common_runtime/gpu/gpu_device.cc:1532] Created device /job:worker/replica:0/task:6/device:GPU:0 with 78724 MB memory:  -> device: 6, name: NVIDIA A100-SXM4-80GB, pci bus id: 0000:ca:00.0, compute capability: 8.0
2022-12-12 03:51:53.082171: I tensorflow/core/distributed_runtime/rpc/grpc_channel.cc:272] Initialize GrpcChannelCache for job worker -> {0 -> localhost:12340, 1 -> localhost:12341, 2 -> localhost:12342, 3 -> localhost:12343, 4 -> localhost:12344, 5 -> localhost:12345, 6 -> localhost:12346, 7 -> localhost:12347}
2022-12-12 03:51:53.082270: I tensorflow/core/distributed_runtime/rpc/grpc_channel.cc:272] Initialize GrpcChannelCache for job worker -> {0 -> localhost:12340, 1 -> localhost:12341, 2 -> localhost:12342, 3 -> localhost:12343, 4 -> localhost:12344, 5 -> localhost:12345, 6 -> localhost:12346, 7 -> localhost:12347}
2022-12-12 03:51:53.083160: I tensorflow/core/distributed_runtime/rpc/grpc_channel.cc:272] Initialize GrpcChannelCache for job worker -> {0 -> localhost:12340, 1 -> localhost:12341, 2 -> localhost:12342, 3 -> localhost:12343, 4 -> localhost:12344, 5 -> localhost:12345, 6 -> localhost:12346, 7 -> localhost:12347}
2022-12-12 03:51:53.083238: I tensorflow/core/distributed_runtime/rpc/grpc_channel.cc:272] Initialize GrpcChannelCache for job worker -> {0 -> localhost:12340, 1 -> localhost:12341, 2 -> localhost:12342, 3 -> localhost:12343, 4 -> localhost:12344, 5 -> localhost:12345, 6 -> localhost:12346, 7 -> localhost:12347}
2022-12-12 03:51:53.083244: I tensorflow/core/distributed_runtime/rpc/grpc_server_lib.cc:438] Started server with target: grpc://localhost:12344
2022-12-12 03:51:53.084140: I tensorflow/core/distributed_runtime/rpc/grpc_server_lib.cc:438] Started server with target: grpc://localhost:12340
2022-12-12 03:51:53.092912: W tensorflow/core/common_runtime/gpu/gpu_bfc_allocator.cc:42] Overriding orig_value setting because the TF_FORCE_GPU_ALLOW_GROWTH environment variable is set. Original config value was 0.
2022-12-12 03:51:53.092960: I tensorflow/core/common_runtime/gpu/gpu_device.cc:1532] Created device /job:localhost/replica:0/task:0/device:GPU:0 with 78724 MB memory:  -> device: 3, name: NVIDIA A100-SXM4-80GB, pci bus id: 0000:55:00.0, compute capability: 8.0
2022-12-12 03:51:53.100355: I tensorflow/core/distributed_runtime/rpc/grpc_channel.cc:272] Initialize GrpcChannelCache for job worker -> {0 -> localhost:12340, 1 -> localhost:12341, 2 -> localhost:12342, 3 -> localhost:12343, 4 -> localhost:12344, 5 -> localhost:12345, 6 -> localhost:12346, 7 -> localhost:12347}
2022-12-12 03:51:53.100459: I tensorflow/core/distributed_runtime/rpc/grpc_channel.cc:272] Initialize GrpcChannelCache for job worker -> {0 -> localhost:12340, 1 -> localhost:12341, 2 -> localhost:12342, 3 -> localhost:12343, 4 -> localhost:12344, 5 -> localhost:12345, 6 -> localhost:12346, 7 -> localhost:12347}
2022-12-12 03:51:53.101233: I tensorflow/core/distributed_runtime/rpc/grpc_server_lib.cc:438] Started server with target: grpc://localhost:12346
2022-12-12 03:51:53.106264: I tensorflow/core/common_runtime/gpu/gpu_device.cc:1532] Created device /job:worker/replica:0/task:3/device:GPU:0 with 78724 MB memory:  -> device: 3, name: NVIDIA A100-SXM4-80GB, pci bus id: 0000:55:00.0, compute capability: 8.0
2022-12-12 03:51:53.111035: W tensorflow/core/common_runtime/gpu/gpu_bfc_allocator.cc:42] Overriding orig_value setting because the TF_FORCE_GPU_ALLOW_GROWTH environment variable is set. Original config value was 0.
2022-12-12 03:51:53.111074: I tensorflow/core/common_runtime/gpu/gpu_device.cc:1532] Created device /job:localhost/replica:0/task:0/device:GPU:0 with 78724 MB memory:  -> device: 5, name: NVIDIA A100-SXM4-80GB, pci bus id: 0000:93:00.0, compute capability: 8.0
2022-12-12 03:51:53.124381: I tensorflow/core/common_runtime/gpu/gpu_device.cc:1532] Created device /job:worker/replica:0/task:5/device:GPU:0 with 78724 MB memory:  -> device: 5, name: NVIDIA A100-SXM4-80GB, pci bus id: 0000:93:00.0, compute capability: 8.0
2022-12-12 03:51:53.142548: I tensorflow/core/distributed_runtime/rpc/grpc_channel.cc:272] Initialize GrpcChannelCache for job worker -> {0 -> localhost:12340, 1 -> localhost:12341, 2 -> localhost:12342, 3 -> localhost:12343, 4 -> localhost:12344, 5 -> localhost:12345, 6 -> localhost:12346, 7 -> localhost:12347}
2022-12-12 03:51:53.142647: I tensorflow/core/distributed_runtime/rpc/grpc_channel.cc:272] Initialize GrpcChannelCache for job worker -> {0 -> localhost:12340, 1 -> localhost:12341, 2 -> localhost:12342, 3 -> localhost:12343, 4 -> localhost:12344, 5 -> localhost:12345, 6 -> localhost:12346, 7 -> localhost:12347}
2022-12-12 03:51:53.143418: I tensorflow/core/distributed_runtime/rpc/grpc_server_lib.cc:438] Started server with target: grpc://localhost:12345
2022-12-12 03:51:53.148642: I tensorflow/core/distributed_runtime/rpc/grpc_channel.cc:272] Initialize GrpcChannelCache for job worker -> {0 -> localhost:12340, 1 -> localhost:12341, 2 -> localhost:12342, 3 -> localhost:12343, 4 -> localhost:12344, 5 -> localhost:12345, 6 -> localhost:12346, 7 -> localhost:12347}
2022-12-12 03:51:53.148726: I tensorflow/core/distributed_runtime/rpc/grpc_channel.cc:272] Initialize GrpcChannelCache for job worker -> {0 -> localhost:12340, 1 -> localhost:12341, 2 -> localhost:12342, 3 -> localhost:12343, 4 -> localhost:12344, 5 -> localhost:12345, 6 -> localhost:12346, 7 -> localhost:12347}
2022-12-12 03:51:53.149457: I tensorflow/core/distributed_runtime/rpc/grpc_server_lib.cc:438] Started server with target: grpc://localhost:12343
[HCTR][03:51:55.186][ERROR][RK0][main]: using mock embedding with 882774585 * 128 elements
[HCTR][03:51:55.187][ERROR][RK0][main]: using mock embedding with 882774585 * 128 elements
[HCTR][03:51:55.191][ERROR][RK0][main]: using mock embedding with 882774585 * 128 elements
[HCTR][03:51:55.193][ERROR][RK0][main]: using mock embedding with 882774585 * 128 elements
[HCTR][03:51:55.194][ERROR][RK0][main]: using mock embedding with 882774585 * 128 elements
[HCTR][03:51:55.206][ERROR][RK0][main]: using mock embedding with 882774585 * 128 elements
[HCTR][03:51:55.211][ERROR][RK0][main]: using mock embedding with 882774585 * 128 elements
[HCTR][03:51:55.211][ERROR][RK0][main]: using mock embedding with 882774585 * 128 elements
2022-12-12 03:52:03.103648: E tensorflow/core/common_runtime/base_collective_executor.cc:249] BaseCollectiveExecutor::StartAbort DEADLINE_EXCEEDED: Deadline Exceeded
Additional GRPC error information from remote target /job:worker/replica:0/task:0:
:{"created":"@1670817123.103510902","description":"Error received from peer ipv4:127.0.0.1:12340","file":"external/com_github_grpc_grpc/src/core/lib/surface/call.cc","file_line":1056,"grpc_message":"Deadline Exceeded","grpc_status":4}
2022-12-12 03:52:03.104291: E tensorflow/core/common_runtime/base_collective_executor.cc:249] BaseCollectiveExecutor::StartAbort DEADLINE_EXCEEDED: Deadline Exceeded
Additional GRPC error information from remote target /job:worker/replica:0/task:0:
:{"created":"@1670817123.104200825","description":"Error received from peer ipv4:127.0.0.1:12340","file":"external/com_github_grpc_grpc/src/core/lib/surface/call.cc","file_line":1056,"grpc_message":"Deadline Exceeded","grpc_status":4}
2022-12-12 03:52:03.104303: E tensorflow/core/common_runtime/base_collective_executor.cc:249] BaseCollectiveExecutor::StartAbort DEADLINE_EXCEEDED: Deadline Exceeded
Additional GRPC error information from remote target /job:worker/replica:0/task:0:
:{"created":"@1670817123.104208477","description":"Error received from peer ipv4:127.0.0.1:12340","file":"external/com_github_grpc_grpc/src/core/lib/surface/call.cc","file_line":1056,"grpc_message":"Deadline Exceeded","grpc_status":4}
2022-12-12 03:52:03.104494: E tensorflow/core/common_runtime/base_collective_executor.cc:249] BaseCollectiveExecutor::StartAbort DEADLINE_EXCEEDED: Deadline Exceeded
Additional GRPC error information from remote target /job:worker/replica:0/task:0:
:{"created":"@1670817123.104402938","description":"Error received from peer ipv4:127.0.0.1:12340","file":"external/com_github_grpc_grpc/src/core/lib/surface/call.cc","file_line":1056,"grpc_message":"Deadline Exceeded","grpc_status":4}
2022-12-12 03:52:03.145901: E tensorflow/core/common_runtime/base_collective_executor.cc:249] BaseCollectiveExecutor::StartAbort DEADLINE_EXCEEDED: Deadline Exceeded
Additional GRPC error information from remote target /job:worker/replica:0/task:0:
:{"created":"@1670817123.145809443","description":"Error received from peer ipv4:127.0.0.1:12340","file":"external/com_github_grpc_grpc/src/core/lib/surface/call.cc","file_line":1056,"grpc_message":"Deadline Exceeded","grpc_status":4}
2022-12-12 03:52:03.152800: E tensorflow/core/common_runtime/base_collective_executor.cc:249] BaseCollectiveExecutor::StartAbort DEADLINE_EXCEEDED: Deadline Exceeded
Additional GRPC error information from remote target /job:worker/replica:0/task:0:
:{"created":"@1670817123.152711475","description":"Error received from peer ipv4:127.0.0.1:12340","file":"external/com_github_grpc_grpc/src/core/lib/surface/call.cc","file_line":1056,"grpc_message":"Deadline Exceeded","grpc_status":4}
2022-12-12 03:52:04.031928: E tensorflow/core/common_runtime/base_collective_executor.cc:249] BaseCollectiveExecutor::StartAbort DEADLINE_EXCEEDED: Deadline Exceeded
Additional GRPC error information from remote target /job:worker/replica:0/task:0:
:{"created":"@1670817124.031771791","description":"Error received from peer ipv4:127.0.0.1:12340","file":"external/com_github_grpc_grpc/src/core/lib/surface/call.cc","file_line":1056,"grpc_message":"Deadline Exceeded","grpc_status":4}
2022-12-12 03:52:13.309522: E tensorflow/core/common_runtime/base_collective_executor.cc:249] BaseCollectiveExecutor::StartAbort UNAVAILABLE: Task /job:worker/replica:0/task:0 heartbeat timeout. This indicates that the remote task has failed, got preempted, or crashed unexpectedly.
Additional GRPC error information from remote target /job:worker/replica:0/task:0:
:{"created":"@1670817133.309170470","description":"Error received from peer ipv4:127.0.0.1:12340","file":"external/com_github_grpc_grpc/src/core/lib/surface/call.cc","file_line":1056,"grpc_message":"Task /job:worker/replica:0/task:0 heartbeat timeout. This indicates that the remote task has failed, got preempted, or crashed unexpectedly.","grpc_status":14} [type.googleapis.com/tensorflow.CoordinationServiceError='']
Process Process-7:
Traceback (most recent call last):
  File "/usr/lib/python3.8/multiprocessing/process.py", line 315, in _bootstrap
    self.run()
  File "/usr/lib/python3.8/multiprocessing/process.py", line 108, in run
    self._target(*self._args, **self._kwargs)
  File "../examples/inference.py", line 211, in proc_func
    embeddings_peek, inputs_peek = inference_with_saved_model(args)
  File "../examples/inference.py", line 101, in inference_with_saved_model
    model = prepare_model(args)
  File "../examples/inference.py", line 80, in prepare_model
    model = DLRMHPS("mean", args["max_vocabulary_size"] // args["gpu_num"], args["embed_vec_size"], args["slot_num"], args["dense_dim"],
  File "/hugectr_dev/study/examples/model_zoo.py", line 145, in __init__
    super(DLRMHPS, self).__init__(**kwargs)
  File "/usr/local/lib/python3.8/dist-packages/tensorflow/python/training/tracking/base.py", line 587, in _method_wrapper
    result = method(self, *args, **kwargs)
  File "/usr/local/lib/python3.8/dist-packages/keras/utils/traceback_utils.py", line 67, in error_handler
    raise e.with_traceback(filtered_tb) from None
  File "/usr/local/lib/python3.8/dist-packages/tensorflow/python/eager/execute.py", line 54, in quick_execute
    tensors = pywrap_tfe.TFE_Py_Execute(ctx._handle, device_name, op_name,
tensorflow.python.framework.errors_impl.DeadlineExceededError: Collective ops is aborted by: Deadline Exceeded
Additional GRPC error information from remote target /job:worker/replica:0/task:0:
:{"created":"@1670817123.103510902","description":"Error received from peer ipv4:127.0.0.1:12340","file":"external/com_github_grpc_grpc/src/core/lib/surface/call.cc","file_line":1056,"grpc_message":"Deadline Exceeded","grpc_status":4}
The error could be from a previous operation. Restart your program to reset. [Op:CollectiveBcastRecv]
Process Process-4:
Traceback (most recent call last):
  File "/usr/lib/python3.8/multiprocessing/process.py", line 315, in _bootstrap
    self.run()
  File "/usr/lib/python3.8/multiprocessing/process.py", line 108, in run
    self._target(*self._args, **self._kwargs)
  File "../examples/inference.py", line 211, in proc_func
    embeddings_peek, inputs_peek = inference_with_saved_model(args)
  File "../examples/inference.py", line 101, in inference_with_saved_model
    model = prepare_model(args)
  File "../examples/inference.py", line 80, in prepare_model
    model = DLRMHPS("mean", args["max_vocabulary_size"] // args["gpu_num"], args["embed_vec_size"], args["slot_num"], args["dense_dim"],
  File "/hugectr_dev/study/examples/model_zoo.py", line 145, in __init__
    super(DLRMHPS, self).__init__(**kwargs)
  File "/usr/local/lib/python3.8/dist-packages/tensorflow/python/training/tracking/base.py", line 587, in _method_wrapper
    result = method(self, *args, **kwargs)
  File "/usr/local/lib/python3.8/dist-packages/keras/utils/traceback_utils.py", line 67, in error_handler
    raise e.with_traceback(filtered_tb) from None
  File "/usr/local/lib/python3.8/dist-packages/tensorflow/python/eager/execute.py", line 54, in quick_execute
    tensors = pywrap_tfe.TFE_Py_Execute(ctx._handle, device_name, op_name,
tensorflow.python.framework.errors_impl.DeadlineExceededError: Collective ops is aborted by: Deadline Exceeded
Additional GRPC error information from remote target /job:worker/replica:0/task:0:
:{"created":"@1670817123.152711475","description":"Error received from peer ipv4:127.0.0.1:12340","file":"external/com_github_grpc_grpc/src/core/lib/surface/call.cc","file_line":1056,"grpc_message":"Deadline Exceeded","grpc_status":4}
The error could be from a previous operation. Restart your program to reset. [Op:CollectiveBcastRecv]
Process Process-3:
Traceback (most recent call last):
  File "/usr/lib/python3.8/multiprocessing/process.py", line 315, in _bootstrap
    self.run()
  File "/usr/lib/python3.8/multiprocessing/process.py", line 108, in run
    self._target(*self._args, **self._kwargs)
  File "../examples/inference.py", line 211, in proc_func
    embeddings_peek, inputs_peek = inference_with_saved_model(args)
  File "../examples/inference.py", line 101, in inference_with_saved_model
    model = prepare_model(args)
  File "../examples/inference.py", line 80, in prepare_model
    model = DLRMHPS("mean", args["max_vocabulary_size"] // args["gpu_num"], args["embed_vec_size"], args["slot_num"], args["dense_dim"],
  File "/hugectr_dev/study/examples/model_zoo.py", line 145, in __init__
    super(DLRMHPS, self).__init__(**kwargs)
  File "/usr/local/lib/python3.8/dist-packages/tensorflow/python/training/tracking/base.py", line 587, in _method_wrapper
    result = method(self, *args, **kwargs)
  File "/usr/local/lib/python3.8/dist-packages/keras/utils/traceback_utils.py", line 67, in error_handler
    raise e.with_traceback(filtered_tb) from None
  File "/usr/local/lib/python3.8/dist-packages/tensorflow/python/eager/execute.py", line 54, in quick_execute
    tensors = pywrap_tfe.TFE_Py_Execute(ctx._handle, device_name, op_name,
tensorflow.python.framework.errors_impl.DeadlineExceededError: Collective ops is aborted by: Deadline Exceeded
Additional GRPC error information from remote target /job:worker/replica:0/task:0:
:{"created":"@1670817123.104200825","description":"Error received from peer ipv4:127.0.0.1:12340","file":"external/com_github_grpc_grpc/src/core/lib/surface/call.cc","file_line":1056,"grpc_message":"Deadline Exceeded","grpc_status":4}
The error could be from a previous operation. Restart your program to reset. [Op:CollectiveBcastRecv]
Process Process-5:
Traceback (most recent call last):
  File "/usr/lib/python3.8/multiprocessing/process.py", line 315, in _bootstrap
    self.run()
  File "/usr/lib/python3.8/multiprocessing/process.py", line 108, in run
    self._target(*self._args, **self._kwargs)
  File "../examples/inference.py", line 211, in proc_func
    embeddings_peek, inputs_peek = inference_with_saved_model(args)
  File "../examples/inference.py", line 101, in inference_with_saved_model
    model = prepare_model(args)
  File "../examples/inference.py", line 80, in prepare_model
    model = DLRMHPS("mean", args["max_vocabulary_size"] // args["gpu_num"], args["embed_vec_size"], args["slot_num"], args["dense_dim"],
  File "/hugectr_dev/study/examples/model_zoo.py", line 145, in __init__
    super(DLRMHPS, self).__init__(**kwargs)
  File "/usr/local/lib/python3.8/dist-packages/tensorflow/python/training/tracking/base.py", line 587, in _method_wrapper
    result = method(self, *args, **kwargs)
  File "/usr/local/lib/python3.8/dist-packages/keras/utils/traceback_utils.py", line 67, in error_handler
    raise e.with_traceback(filtered_tb) from None
  File "/usr/local/lib/python3.8/dist-packages/tensorflow/python/eager/execute.py", line 54, in quick_execute
    tensors = pywrap_tfe.TFE_Py_Execute(ctx._handle, device_name, op_name,
tensorflow.python.framework.errors_impl.DeadlineExceededError: Collective ops is aborted by: Deadline Exceeded
Additional GRPC error information from remote target /job:worker/replica:0/task:0:
:{"created":"@1670817123.104208477","description":"Error received from peer ipv4:127.0.0.1:12340","file":"external/com_github_grpc_grpc/src/core/lib/surface/call.cc","file_line":1056,"grpc_message":"Deadline Exceeded","grpc_status":4}
The error could be from a previous operation. Restart your program to reset. [Op:CollectiveBcastRecv]
Process Process-2:
Traceback (most recent call last):
  File "/usr/lib/python3.8/multiprocessing/process.py", line 315, in _bootstrap
    self.run()
  File "/usr/lib/python3.8/multiprocessing/process.py", line 108, in run
    self._target(*self._args, **self._kwargs)
  File "../examples/inference.py", line 211, in proc_func
    embeddings_peek, inputs_peek = inference_with_saved_model(args)
  File "../examples/inference.py", line 101, in inference_with_saved_model
    model = prepare_model(args)
  File "../examples/inference.py", line 80, in prepare_model
    model = DLRMHPS("mean", args["max_vocabulary_size"] // args["gpu_num"], args["embed_vec_size"], args["slot_num"], args["dense_dim"],
  File "/hugectr_dev/study/examples/model_zoo.py", line 145, in __init__
    super(DLRMHPS, self).__init__(**kwargs)
  File "/usr/local/lib/python3.8/dist-packages/tensorflow/python/training/tracking/base.py", line 587, in _method_wrapper
    result = method(self, *args, **kwargs)
  File "/usr/local/lib/python3.8/dist-packages/keras/utils/traceback_utils.py", line 67, in error_handler
    raise e.with_traceback(filtered_tb) from None
  File "/usr/local/lib/python3.8/dist-packages/tensorflow/python/eager/execute.py", line 54, in quick_execute
    tensors = pywrap_tfe.TFE_Py_Execute(ctx._handle, device_name, op_name,
tensorflow.python.framework.errors_impl.DeadlineExceededError: Collective ops is aborted by: Deadline Exceeded
Additional GRPC error information from remote target /job:worker/replica:0/task:0:
:{"created":"@1670817124.031771791","description":"Error received from peer ipv4:127.0.0.1:12340","file":"external/com_github_grpc_grpc/src/core/lib/surface/call.cc","file_line":1056,"grpc_message":"Deadline Exceeded","grpc_status":4}
The error could be from a previous operation. Restart your program to reset. [Op:CollectiveBcastRecv]
Process Process-8:
Traceback (most recent call last):
  File "/usr/lib/python3.8/multiprocessing/process.py", line 315, in _bootstrap
    self.run()
  File "/usr/lib/python3.8/multiprocessing/process.py", line 108, in run
    self._target(*self._args, **self._kwargs)
  File "../examples/inference.py", line 211, in proc_func
    embeddings_peek, inputs_peek = inference_with_saved_model(args)
  File "../examples/inference.py", line 101, in inference_with_saved_model
    model = prepare_model(args)
  File "../examples/inference.py", line 80, in prepare_model
    model = DLRMHPS("mean", args["max_vocabulary_size"] // args["gpu_num"], args["embed_vec_size"], args["slot_num"], args["dense_dim"],
  File "/hugectr_dev/study/examples/model_zoo.py", line 145, in __init__
    super(DLRMHPS, self).__init__(**kwargs)
  File "/usr/local/lib/python3.8/dist-packages/tensorflow/python/training/tracking/base.py", line 587, in _method_wrapper
    result = method(self, *args, **kwargs)
  File "/usr/local/lib/python3.8/dist-packages/keras/utils/traceback_utils.py", line 67, in error_handler
    raise e.with_traceback(filtered_tb) from None
  File "/usr/local/lib/python3.8/dist-packages/tensorflow/python/eager/execute.py", line 54, in quick_execute
    tensors = pywrap_tfe.TFE_Py_Execute(ctx._handle, device_name, op_name,
tensorflow.python.framework.errors_impl.DeadlineExceededError: Collective ops is aborted by: Deadline Exceeded
Additional GRPC error information from remote target /job:worker/replica:0/task:0:
:{"created":"@1670817123.104402938","description":"Error received from peer ipv4:127.0.0.1:12340","file":"external/com_github_grpc_grpc/src/core/lib/surface/call.cc","file_line":1056,"grpc_message":"Deadline Exceeded","grpc_status":4}
The error could be from a previous operation. Restart your program to reset. [Op:CollectiveBcastRecv]
Process Process-6:
Traceback (most recent call last):
  File "/usr/lib/python3.8/multiprocessing/process.py", line 315, in _bootstrap
    self.run()
  File "/usr/lib/python3.8/multiprocessing/process.py", line 108, in run
    self._target(*self._args, **self._kwargs)
  File "../examples/inference.py", line 211, in proc_func
    embeddings_peek, inputs_peek = inference_with_saved_model(args)
  File "../examples/inference.py", line 101, in inference_with_saved_model
    model = prepare_model(args)
  File "../examples/inference.py", line 80, in prepare_model
    model = DLRMHPS("mean", args["max_vocabulary_size"] // args["gpu_num"], args["embed_vec_size"], args["slot_num"], args["dense_dim"],
  File "/hugectr_dev/study/examples/model_zoo.py", line 145, in __init__
    super(DLRMHPS, self).__init__(**kwargs)
  File "/usr/local/lib/python3.8/dist-packages/tensorflow/python/training/tracking/base.py", line 587, in _method_wrapper
    result = method(self, *args, **kwargs)
  File "/usr/local/lib/python3.8/dist-packages/keras/utils/traceback_utils.py", line 67, in error_handler
    raise e.with_traceback(filtered_tb) from None
  File "/usr/local/lib/python3.8/dist-packages/tensorflow/python/eager/execute.py", line 54, in quick_execute
    tensors = pywrap_tfe.TFE_Py_Execute(ctx._handle, device_name, op_name,
tensorflow.python.framework.errors_impl.DeadlineExceededError: Collective ops is aborted by: Deadline Exceeded
Additional GRPC error information from remote target /job:worker/replica:0/task:0:
:{"created":"@1670817123.145809443","description":"Error received from peer ipv4:127.0.0.1:12340","file":"external/com_github_grpc_grpc/src/core/lib/surface/call.cc","file_line":1056,"grpc_message":"Deadline Exceeded","grpc_status":4}
The error could be from a previous operation. Restart your program to reset. [Op:CollectiveBcastRecv]
Process Process-1:
Traceback (most recent call last):
  File "/usr/lib/python3.8/multiprocessing/process.py", line 315, in _bootstrap
    self.run()
  File "/usr/lib/python3.8/multiprocessing/process.py", line 108, in run
    self._target(*self._args, **self._kwargs)
  File "../examples/inference.py", line 211, in proc_func
    embeddings_peek, inputs_peek = inference_with_saved_model(args)
  File "../examples/inference.py", line 101, in inference_with_saved_model
    model = prepare_model(args)
  File "../examples/inference.py", line 80, in prepare_model
    model = DLRMHPS("mean", args["max_vocabulary_size"] // args["gpu_num"], args["embed_vec_size"], args["slot_num"], args["dense_dim"],
  File "/hugectr_dev/study/examples/model_zoo.py", line 145, in __init__
    super(DLRMHPS, self).__init__(**kwargs)
  File "/usr/local/lib/python3.8/dist-packages/tensorflow/python/training/tracking/base.py", line 587, in _method_wrapper
    result = method(self, *args, **kwargs)
  File "/usr/local/lib/python3.8/dist-packages/keras/utils/traceback_utils.py", line 67, in error_handler
    raise e.with_traceback(filtered_tb) from None
  File "/usr/local/lib/python3.8/dist-packages/tensorflow/python/eager/execute.py", line 54, in quick_execute
    tensors = pywrap_tfe.TFE_Py_Execute(ctx._handle, device_name, op_name,
tensorflow.python.framework.errors_impl.UnavailableError: Collective ops is aborted by: Task /job:worker/replica:0/task:0 heartbeat timeout. This indicates that the remote task has failed, got preempted, or crashed unexpectedly.
Additional GRPC error information from remote target /job:worker/replica:0/task:0:
:{"created":"@1670817133.309170470","description":"Error received from peer ipv4:127.0.0.1:12340","file":"external/com_github_grpc_grpc/src/core/lib/surface/call.cc","file_line":1056,"grpc_message":"Task /job:worker/replica:0/task:0 heartbeat timeout. This indicates that the remote task has failed, got preempted, or crashed unexpectedly.","grpc_status":14}
The error could be from a previous operation. Restart your program to reset. [Op:CollectiveBcastSend]
