2022-12-12 02:53:05.633752: I tensorflow/core/util/util.cc:169] oneDNN custom operations are on. You may see slightly different numerical results due to floating-point round-off errors from different computation orders. To turn them off, set the environment variable `TF_ENABLE_ONEDNN_OPTS=0`.
2022-12-12 02:53:13.544484: I tensorflow/core/platform/cpu_feature_guard.cc:194] This TensorFlow binary is optimized with oneAPI Deep Neural Network Library (oneDNN) to use the following CPU instructions in performance-critical operations:  SSE3 SSE4.1 SSE4.2 AVX
To enable them in other operations, rebuild TensorFlow with the appropriate compiler flags.
2022-12-12 02:53:13.632086: I tensorflow/core/platform/cpu_feature_guard.cc:194] This TensorFlow binary is optimized with oneAPI Deep Neural Network Library (oneDNN) to use the following CPU instructions in performance-critical operations:  SSE3 SSE4.1 SSE4.2 AVX
To enable them in other operations, rebuild TensorFlow with the appropriate compiler flags.
2022-12-12 02:53:13.738044: I tensorflow/core/platform/cpu_feature_guard.cc:194] This TensorFlow binary is optimized with oneAPI Deep Neural Network Library (oneDNN) to use the following CPU instructions in performance-critical operations:  SSE3 SSE4.1 SSE4.2 AVX
To enable them in other operations, rebuild TensorFlow with the appropriate compiler flags.
2022-12-12 02:53:13.781180: I tensorflow/core/platform/cpu_feature_guard.cc:194] This TensorFlow binary is optimized with oneAPI Deep Neural Network Library (oneDNN) to use the following CPU instructions in performance-critical operations:  SSE3 SSE4.1 SSE4.2 AVX
To enable them in other operations, rebuild TensorFlow with the appropriate compiler flags.
2022-12-12 02:53:13.811551: I tensorflow/core/platform/cpu_feature_guard.cc:194] This TensorFlow binary is optimized with oneAPI Deep Neural Network Library (oneDNN) to use the following CPU instructions in performance-critical operations:  SSE3 SSE4.1 SSE4.2 AVX
To enable them in other operations, rebuild TensorFlow with the appropriate compiler flags.
2022-12-12 02:53:13.822817: I tensorflow/core/platform/cpu_feature_guard.cc:194] This TensorFlow binary is optimized with oneAPI Deep Neural Network Library (oneDNN) to use the following CPU instructions in performance-critical operations:  SSE3 SSE4.1 SSE4.2 AVX
To enable them in other operations, rebuild TensorFlow with the appropriate compiler flags.
2022-12-12 02:53:13.853228: I tensorflow/core/platform/cpu_feature_guard.cc:194] This TensorFlow binary is optimized with oneAPI Deep Neural Network Library (oneDNN) to use the following CPU instructions in performance-critical operations:  SSE3 SSE4.1 SSE4.2 AVX
To enable them in other operations, rebuild TensorFlow with the appropriate compiler flags.
2022-12-12 02:53:13.888223: I tensorflow/core/platform/cpu_feature_guard.cc:194] This TensorFlow binary is optimized with oneAPI Deep Neural Network Library (oneDNN) to use the following CPU instructions in performance-critical operations:  SSE3 SSE4.1 SSE4.2 AVX
To enable them in other operations, rebuild TensorFlow with the appropriate compiler flags.
2022-12-12 02:53:15.961767: W tensorflow/core/common_runtime/gpu/gpu_bfc_allocator.cc:42] Overriding orig_value setting because the TF_FORCE_GPU_ALLOW_GROWTH environment variable is set. Original config value was 0.
2022-12-12 02:53:15.961834: I tensorflow/core/common_runtime/gpu/gpu_device.cc:1532] Created device /job:localhost/replica:0/task:0/device:GPU:0 with 78724 MB memory:  -> device: 1, name: NVIDIA A100-SXM4-80GB, pci bus id: 0000:25:00.0, compute capability: 8.0
2022-12-12 02:53:15.976608: I tensorflow/core/common_runtime/gpu/gpu_device.cc:1532] Created device /job:worker/replica:0/task:1/device:GPU:0 with 78724 MB memory:  -> device: 1, name: NVIDIA A100-SXM4-80GB, pci bus id: 0000:25:00.0, compute capability: 8.0
2022-12-12 02:53:15.997982: I tensorflow/core/distributed_runtime/rpc/grpc_channel.cc:272] Initialize GrpcChannelCache for job worker -> {0 -> localhost:12340, 1 -> localhost:12341, 2 -> localhost:12342, 3 -> localhost:12343, 4 -> localhost:12344, 5 -> localhost:12345, 6 -> localhost:12346, 7 -> localhost:12347}
2022-12-12 02:53:15.998134: I tensorflow/core/distributed_runtime/rpc/grpc_channel.cc:272] Initialize GrpcChannelCache for job worker -> {0 -> localhost:12340, 1 -> localhost:12341, 2 -> localhost:12342, 3 -> localhost:12343, 4 -> localhost:12344, 5 -> localhost:12345, 6 -> localhost:12346, 7 -> localhost:12347}
2022-12-12 02:53:16.008301: I tensorflow/core/distributed_runtime/rpc/grpc_server_lib.cc:438] Started server with target: grpc://localhost:12341
2022-12-12 02:53:16.010570: W tensorflow/core/common_runtime/gpu/gpu_bfc_allocator.cc:42] Overriding orig_value setting because the TF_FORCE_GPU_ALLOW_GROWTH environment variable is set. Original config value was 0.
2022-12-12 02:53:16.010628: I tensorflow/core/common_runtime/gpu/gpu_device.cc:1532] Created device /job:localhost/replica:0/task:0/device:GPU:0 with 78724 MB memory:  -> device: 2, name: NVIDIA A100-SXM4-80GB, pci bus id: 0000:50:00.0, compute capability: 8.0
2022-12-12 02:53:16.025784: I tensorflow/core/common_runtime/gpu/gpu_device.cc:1532] Created device /job:worker/replica:0/task:2/device:GPU:0 with 78724 MB memory:  -> device: 2, name: NVIDIA A100-SXM4-80GB, pci bus id: 0000:50:00.0, compute capability: 8.0
2022-12-12 02:53:16.046759: W tensorflow/core/common_runtime/gpu/gpu_bfc_allocator.cc:42] Overriding orig_value setting because the TF_FORCE_GPU_ALLOW_GROWTH environment variable is set. Original config value was 0.
2022-12-12 02:53:16.046822: I tensorflow/core/common_runtime/gpu/gpu_device.cc:1532] Created device /job:localhost/replica:0/task:0/device:GPU:0 with 78724 MB memory:  -> device: 6, name: NVIDIA A100-SXM4-80GB, pci bus id: 0000:ca:00.0, compute capability: 8.0
2022-12-12 02:53:16.052469: W tensorflow/core/common_runtime/gpu/gpu_bfc_allocator.cc:42] Overriding orig_value setting because the TF_FORCE_GPU_ALLOW_GROWTH environment variable is set. Original config value was 0.
2022-12-12 02:53:16.052538: I tensorflow/core/common_runtime/gpu/gpu_device.cc:1532] Created device /job:localhost/replica:0/task:0/device:GPU:0 with 78724 MB memory:  -> device: 3, name: NVIDIA A100-SXM4-80GB, pci bus id: 0000:55:00.0, compute capability: 8.0
2022-12-12 02:53:16.061253: I tensorflow/core/common_runtime/gpu/gpu_device.cc:1532] Created device /job:worker/replica:0/task:6/device:GPU:0 with 78724 MB memory:  -> device: 6, name: NVIDIA A100-SXM4-80GB, pci bus id: 0000:ca:00.0, compute capability: 8.0
2022-12-12 02:53:16.064971: W tensorflow/core/common_runtime/gpu/gpu_bfc_allocator.cc:42] Overriding orig_value setting because the TF_FORCE_GPU_ALLOW_GROWTH environment variable is set. Original config value was 0.
2022-12-12 02:53:16.065023: I tensorflow/core/common_runtime/gpu/gpu_device.cc:1532] Created device /job:localhost/replica:0/task:0/device:GPU:0 with 78724 MB memory:  -> device: 7, name: NVIDIA A100-SXM4-80GB, pci bus id: 0000:d0:00.0, compute capability: 8.0
2022-12-12 02:53:16.065758: W tensorflow/core/common_runtime/gpu/gpu_bfc_allocator.cc:42] Overriding orig_value setting because the TF_FORCE_GPU_ALLOW_GROWTH environment variable is set. Original config value was 0.
2022-12-12 02:53:16.065802: I tensorflow/core/common_runtime/gpu/gpu_device.cc:1532] Created device /job:localhost/replica:0/task:0/device:GPU:0 with 78724 MB memory:  -> device: 0, name: NVIDIA A100-SXM4-80GB, pci bus id: 0000:1f:00.0, compute capability: 8.0
2022-12-12 02:53:16.066838: I tensorflow/core/distributed_runtime/rpc/grpc_channel.cc:272] Initialize GrpcChannelCache for job worker -> {0 -> localhost:12340, 1 -> localhost:12341, 2 -> localhost:12342, 3 -> localhost:12343, 4 -> localhost:12344, 5 -> localhost:12345, 6 -> localhost:12346, 7 -> localhost:12347}
2022-12-12 02:53:16.066937: I tensorflow/core/distributed_runtime/rpc/grpc_channel.cc:272] Initialize GrpcChannelCache for job worker -> {0 -> localhost:12340, 1 -> localhost:12341, 2 -> localhost:12342, 3 -> localhost:12343, 4 -> localhost:12344, 5 -> localhost:12345, 6 -> localhost:12346, 7 -> localhost:12347}
2022-12-12 02:53:16.067680: I tensorflow/core/distributed_runtime/rpc/grpc_server_lib.cc:438] Started server with target: grpc://localhost:12342
2022-12-12 02:53:16.071174: I tensorflow/core/common_runtime/gpu/gpu_device.cc:1532] Created device /job:worker/replica:0/task:3/device:GPU:0 with 78724 MB memory:  -> device: 3, name: NVIDIA A100-SXM4-80GB, pci bus id: 0000:55:00.0, compute capability: 8.0
2022-12-12 02:53:16.074414: W tensorflow/core/common_runtime/gpu/gpu_bfc_allocator.cc:42] Overriding orig_value setting because the TF_FORCE_GPU_ALLOW_GROWTH environment variable is set. Original config value was 0.
2022-12-12 02:53:16.074458: I tensorflow/core/common_runtime/gpu/gpu_device.cc:1532] Created device /job:localhost/replica:0/task:0/device:GPU:0 with 78724 MB memory:  -> device: 4, name: NVIDIA A100-SXM4-80GB, pci bus id: 0000:8e:00.0, compute capability: 8.0
2022-12-12 02:53:16.080604: I tensorflow/core/common_runtime/gpu/gpu_device.cc:1532] Created device /job:worker/replica:0/task:7/device:GPU:0 with 78724 MB memory:  -> device: 7, name: NVIDIA A100-SXM4-80GB, pci bus id: 0000:d0:00.0, compute capability: 8.0
2022-12-12 02:53:16.082052: I tensorflow/core/common_runtime/gpu/gpu_device.cc:1532] Created device /job:worker/replica:0/task:0/device:GPU:0 with 78724 MB memory:  -> device: 0, name: NVIDIA A100-SXM4-80GB, pci bus id: 0000:1f:00.0, compute capability: 8.0
2022-12-12 02:53:16.082573: I tensorflow/core/distributed_runtime/rpc/grpc_channel.cc:272] Initialize GrpcChannelCache for job worker -> {0 -> localhost:12340, 1 -> localhost:12341, 2 -> localhost:12342, 3 -> localhost:12343, 4 -> localhost:12344, 5 -> localhost:12345, 6 -> localhost:12346, 7 -> localhost:12347}
2022-12-12 02:53:16.082655: I tensorflow/core/distributed_runtime/rpc/grpc_channel.cc:272] Initialize GrpcChannelCache for job worker -> {0 -> localhost:12340, 1 -> localhost:12341, 2 -> localhost:12342, 3 -> localhost:12343, 4 -> localhost:12344, 5 -> localhost:12345, 6 -> localhost:12346, 7 -> localhost:12347}
2022-12-12 02:53:16.083403: I tensorflow/core/distributed_runtime/rpc/grpc_server_lib.cc:438] Started server with target: grpc://localhost:12346
2022-12-12 02:53:16.086978: W tensorflow/core/common_runtime/gpu/gpu_bfc_allocator.cc:42] Overriding orig_value setting because the TF_FORCE_GPU_ALLOW_GROWTH environment variable is set. Original config value was 0.
2022-12-12 02:53:16.087018: I tensorflow/core/common_runtime/gpu/gpu_device.cc:1532] Created device /job:localhost/replica:0/task:0/device:GPU:0 with 78724 MB memory:  -> device: 5, name: NVIDIA A100-SXM4-80GB, pci bus id: 0000:93:00.0, compute capability: 8.0
2022-12-12 02:53:16.088974: I tensorflow/core/common_runtime/gpu/gpu_device.cc:1532] Created device /job:worker/replica:0/task:4/device:GPU:0 with 78724 MB memory:  -> device: 4, name: NVIDIA A100-SXM4-80GB, pci bus id: 0000:8e:00.0, compute capability: 8.0
2022-12-12 02:53:16.101124: I tensorflow/core/common_runtime/gpu/gpu_device.cc:1532] Created device /job:worker/replica:0/task:5/device:GPU:0 with 78724 MB memory:  -> device: 5, name: NVIDIA A100-SXM4-80GB, pci bus id: 0000:93:00.0, compute capability: 8.0
2022-12-12 02:53:16.101741: I tensorflow/core/distributed_runtime/rpc/grpc_channel.cc:272] Initialize GrpcChannelCache for job worker -> {0 -> localhost:12340, 1 -> localhost:12341, 2 -> localhost:12342, 3 -> localhost:12343, 4 -> localhost:12344, 5 -> localhost:12345, 6 -> localhost:12346, 7 -> localhost:12347}
2022-12-12 02:53:16.101835: I tensorflow/core/distributed_runtime/rpc/grpc_channel.cc:272] Initialize GrpcChannelCache for job worker -> {0 -> localhost:12340, 1 -> localhost:12341, 2 -> localhost:12342, 3 -> localhost:12343, 4 -> localhost:12344, 5 -> localhost:12345, 6 -> localhost:12346, 7 -> localhost:12347}
2022-12-12 02:53:16.102561: I tensorflow/core/distributed_runtime/rpc/grpc_server_lib.cc:438] Started server with target: grpc://localhost:12347
2022-12-12 02:53:16.102590: I tensorflow/core/distributed_runtime/rpc/grpc_channel.cc:272] Initialize GrpcChannelCache for job worker -> {0 -> localhost:12340, 1 -> localhost:12341, 2 -> localhost:12342, 3 -> localhost:12343, 4 -> localhost:12344, 5 -> localhost:12345, 6 -> localhost:12346, 7 -> localhost:12347}
2022-12-12 02:53:16.102670: I tensorflow/core/distributed_runtime/rpc/grpc_channel.cc:272] Initialize GrpcChannelCache for job worker -> {0 -> localhost:12340, 1 -> localhost:12341, 2 -> localhost:12342, 3 -> localhost:12343, 4 -> localhost:12344, 5 -> localhost:12345, 6 -> localhost:12346, 7 -> localhost:12347}
2022-12-12 02:53:16.103415: I tensorflow/core/distributed_runtime/rpc/grpc_server_lib.cc:438] Started server with target: grpc://localhost:12340
2022-12-12 02:53:16.110093: I tensorflow/core/distributed_runtime/rpc/grpc_channel.cc:272] Initialize GrpcChannelCache for job worker -> {0 -> localhost:12340, 1 -> localhost:12341, 2 -> localhost:12342, 3 -> localhost:12343, 4 -> localhost:12344, 5 -> localhost:12345, 6 -> localhost:12346, 7 -> localhost:12347}
2022-12-12 02:53:16.110180: I tensorflow/core/distributed_runtime/rpc/grpc_channel.cc:272] Initialize GrpcChannelCache for job worker -> {0 -> localhost:12340, 1 -> localhost:12341, 2 -> localhost:12342, 3 -> localhost:12343, 4 -> localhost:12344, 5 -> localhost:12345, 6 -> localhost:12346, 7 -> localhost:12347}
2022-12-12 02:53:16.111851: I tensorflow/core/distributed_runtime/rpc/grpc_server_lib.cc:438] Started server with target: grpc://localhost:12344
2022-12-12 02:53:16.117320: I tensorflow/core/distributed_runtime/rpc/grpc_channel.cc:272] Initialize GrpcChannelCache for job worker -> {0 -> localhost:12340, 1 -> localhost:12341, 2 -> localhost:12342, 3 -> localhost:12343, 4 -> localhost:12344, 5 -> localhost:12345, 6 -> localhost:12346, 7 -> localhost:12347}
2022-12-12 02:53:16.117429: I tensorflow/core/distributed_runtime/rpc/grpc_channel.cc:272] Initialize GrpcChannelCache for job worker -> {0 -> localhost:12340, 1 -> localhost:12341, 2 -> localhost:12342, 3 -> localhost:12343, 4 -> localhost:12344, 5 -> localhost:12345, 6 -> localhost:12346, 7 -> localhost:12347}
2022-12-12 02:53:16.118574: I tensorflow/core/distributed_runtime/rpc/grpc_server_lib.cc:438] Started server with target: grpc://localhost:12343
2022-12-12 02:53:16.122448: I tensorflow/core/distributed_runtime/rpc/grpc_channel.cc:272] Initialize GrpcChannelCache for job worker -> {0 -> localhost:12340, 1 -> localhost:12341, 2 -> localhost:12342, 3 -> localhost:12343, 4 -> localhost:12344, 5 -> localhost:12345, 6 -> localhost:12346, 7 -> localhost:12347}
2022-12-12 02:53:16.122531: I tensorflow/core/distributed_runtime/rpc/grpc_channel.cc:272] Initialize GrpcChannelCache for job worker -> {0 -> localhost:12340, 1 -> localhost:12341, 2 -> localhost:12342, 3 -> localhost:12343, 4 -> localhost:12344, 5 -> localhost:12345, 6 -> localhost:12346, 7 -> localhost:12347}
2022-12-12 02:53:16.123010: I tensorflow/core/distributed_runtime/rpc/grpc_server_lib.cc:438] Started server with target: grpc://localhost:12345
[HCTR][02:53:18.470][ERROR][RK0][main]: using mock embedding with 882774585 * 128 elements
[HCTR][02:53:18.473][ERROR][RK0][main]: using mock embedding with 882774585 * 128 elements
[HCTR][02:53:18.475][ERROR][RK0][main]: using mock embedding with 882774585 * 128 elements
[HCTR][02:53:18.476][ERROR][RK0][main]: using mock embedding with 882774585 * 128 elements
[HCTR][02:53:18.477][ERROR][RK0][main]: using mock embedding with 882774585 * 128 elements
[HCTR][02:53:18.480][ERROR][RK0][main]: using mock embedding with 882774585 * 128 elements
[HCTR][02:53:18.490][ERROR][RK0][main]: using mock embedding with 882774585 * 128 elements
[HCTR][02:53:18.490][ERROR][RK0][main]: using mock embedding with 882774585 * 128 elements
2022-12-12 02:53:26.460701: E tensorflow/core/common_runtime/base_collective_executor.cc:249] BaseCollectiveExecutor::StartAbort DEADLINE_EXCEEDED: Deadline Exceeded
Additional GRPC error information from remote target /job:worker/replica:0/task:0:
:{"created":"@1670813606.460575561","description":"Error received from peer ipv4:127.0.0.1:12340","file":"external/com_github_grpc_grpc/src/core/lib/surface/call.cc","file_line":1056,"grpc_message":"Deadline Exceeded","grpc_status":4}
2022-12-12 02:53:26.460720: E tensorflow/core/common_runtime/base_collective_executor.cc:249] BaseCollectiveExecutor::StartAbort DEADLINE_EXCEEDED: Deadline Exceeded
Additional GRPC error information from remote target /job:worker/replica:0/task:0:
:{"created":"@1670813606.460617267","description":"Error received from peer ipv4:127.0.0.1:12340","file":"external/com_github_grpc_grpc/src/core/lib/surface/call.cc","file_line":1056,"grpc_message":"Deadline Exceeded","grpc_status":4}
2022-12-12 02:53:26.461125: E tensorflow/core/common_runtime/base_collective_executor.cc:249] BaseCollectiveExecutor::StartAbort DEADLINE_EXCEEDED: Deadline Exceeded
Additional GRPC error information from remote target /job:worker/replica:0/task:0:
:{"created":"@1670813606.461048186","description":"Error received from peer ipv4:127.0.0.1:12340","file":"external/com_github_grpc_grpc/src/core/lib/surface/call.cc","file_line":1056,"grpc_message":"Deadline Exceeded","grpc_status":4}
2022-12-12 02:53:26.461466: E tensorflow/core/common_runtime/base_collective_executor.cc:249] BaseCollectiveExecutor::StartAbort DEADLINE_EXCEEDED: Deadline Exceeded
Additional GRPC error information from remote target /job:worker/replica:0/task:0:
:{"created":"@1670813606.461386074","description":"Error received from peer ipv4:127.0.0.1:12340","file":"external/com_github_grpc_grpc/src/core/lib/surface/call.cc","file_line":1056,"grpc_message":"Deadline Exceeded","grpc_status":4}
2022-12-12 02:53:27.010217: E tensorflow/core/common_runtime/base_collective_executor.cc:249] BaseCollectiveExecutor::StartAbort DEADLINE_EXCEEDED: Deadline Exceeded
Additional GRPC error information from remote target /job:worker/replica:0/task:0:
:{"created":"@1670813607.010120560","description":"Error received from peer ipv4:127.0.0.1:12340","file":"external/com_github_grpc_grpc/src/core/lib/surface/call.cc","file_line":1056,"grpc_message":"Deadline Exceeded","grpc_status":4}
2022-12-12 02:53:27.069357: E tensorflow/core/common_runtime/base_collective_executor.cc:249] BaseCollectiveExecutor::StartAbort DEADLINE_EXCEEDED: Deadline Exceeded
Additional GRPC error information from remote target /job:worker/replica:0/task:0:
:{"created":"@1670813607.069278401","description":"Error received from peer ipv4:127.0.0.1:12340","file":"external/com_github_grpc_grpc/src/core/lib/surface/call.cc","file_line":1056,"grpc_message":"Deadline Exceeded","grpc_status":4}
2022-12-12 02:53:27.084797: E tensorflow/core/common_runtime/base_collective_executor.cc:249] BaseCollectiveExecutor::StartAbort DEADLINE_EXCEEDED: Deadline Exceeded
Additional GRPC error information from remote target /job:worker/replica:0/task:0:
:{"created":"@1670813607.084693609","description":"Error received from peer ipv4:127.0.0.1:12340","file":"external/com_github_grpc_grpc/src/core/lib/surface/call.cc","file_line":1056,"grpc_message":"Deadline Exceeded","grpc_status":4}
2022-12-12 02:53:36.310908: E tensorflow/core/common_runtime/base_collective_executor.cc:249] BaseCollectiveExecutor::StartAbort UNAVAILABLE: Task /job:worker/replica:0/task:0 heartbeat timeout. This indicates that the remote task has failed, got preempted, or crashed unexpectedly.
Additional GRPC error information from remote target /job:worker/replica:0/task:0:
:{"created":"@1670813616.310828572","description":"Error received from peer ipv4:127.0.0.1:12340","file":"external/com_github_grpc_grpc/src/core/lib/surface/call.cc","file_line":1056,"grpc_message":"Task /job:worker/replica:0/task:0 heartbeat timeout. This indicates that the remote task has failed, got preempted, or crashed unexpectedly.","grpc_status":14} [type.googleapis.com/tensorflow.CoordinationServiceError='']
Process Process-4:
Traceback (most recent call last):
  File "/usr/lib/python3.8/multiprocessing/process.py", line 315, in _bootstrap
    self.run()
  File "/usr/lib/python3.8/multiprocessing/process.py", line 108, in run
    self._target(*self._args, **self._kwargs)
  File "../examples/inference.py", line 211, in proc_func
    embeddings_peek, inputs_peek = inference_with_saved_model(args)
  File "../examples/inference.py", line 101, in inference_with_saved_model
    model = prepare_model(args)
  File "../examples/inference.py", line 80, in prepare_model
    model = DLRMHPS("mean", args["max_vocabulary_size"] // args["gpu_num"], args["embed_vec_size"], args["slot_num"], args["dense_dim"],
  File "/hugectr_dev/study/examples/model_zoo.py", line 145, in __init__
    super(DLRMHPS, self).__init__(**kwargs)
  File "/usr/local/lib/python3.8/dist-packages/tensorflow/python/training/tracking/base.py", line 587, in _method_wrapper
    result = method(self, *args, **kwargs)
  File "/usr/local/lib/python3.8/dist-packages/keras/utils/traceback_utils.py", line 67, in error_handler
    raise e.with_traceback(filtered_tb) from None
  File "/usr/local/lib/python3.8/dist-packages/tensorflow/python/eager/execute.py", line 54, in quick_execute
    tensors = pywrap_tfe.TFE_Py_Execute(ctx._handle, device_name, op_name,
tensorflow.python.framework.errors_impl.DeadlineExceededError: Collective ops is aborted by: Deadline Exceeded
Additional GRPC error information from remote target /job:worker/replica:0/task:0:
:{"created":"@1670813606.460617267","description":"Error received from peer ipv4:127.0.0.1:12340","file":"external/com_github_grpc_grpc/src/core/lib/surface/call.cc","file_line":1056,"grpc_message":"Deadline Exceeded","grpc_status":4}
The error could be from a previous operation. Restart your program to reset. [Op:CollectiveBcastRecv]
Process Process-7:
Traceback (most recent call last):
  File "/usr/lib/python3.8/multiprocessing/process.py", line 315, in _bootstrap
    self.run()
  File "/usr/lib/python3.8/multiprocessing/process.py", line 108, in run
    self._target(*self._args, **self._kwargs)
  File "../examples/inference.py", line 211, in proc_func
    embeddings_peek, inputs_peek = inference_with_saved_model(args)
  File "../examples/inference.py", line 101, in inference_with_saved_model
    model = prepare_model(args)
  File "../examples/inference.py", line 80, in prepare_model
    model = DLRMHPS("mean", args["max_vocabulary_size"] // args["gpu_num"], args["embed_vec_size"], args["slot_num"], args["dense_dim"],
  File "/hugectr_dev/study/examples/model_zoo.py", line 145, in __init__
    super(DLRMHPS, self).__init__(**kwargs)
  File "/usr/local/lib/python3.8/dist-packages/tensorflow/python/training/tracking/base.py", line 587, in _method_wrapper
    result = method(self, *args, **kwargs)
  File "/usr/local/lib/python3.8/dist-packages/keras/utils/traceback_utils.py", line 67, in error_handler
    raise e.with_traceback(filtered_tb) from None
  File "/usr/local/lib/python3.8/dist-packages/tensorflow/python/eager/execute.py", line 54, in quick_execute
    tensors = pywrap_tfe.TFE_Py_Execute(ctx._handle, device_name, op_name,
tensorflow.python.framework.errors_impl.DeadlineExceededError: Collective ops is aborted by: Deadline Exceeded
Additional GRPC error information from remote target /job:worker/replica:0/task:0:
:{"created":"@1670813607.084693609","description":"Error received from peer ipv4:127.0.0.1:12340","file":"external/com_github_grpc_grpc/src/core/lib/surface/call.cc","file_line":1056,"grpc_message":"Deadline Exceeded","grpc_status":4}
The error could be from a previous operation. Restart your program to reset. [Op:CollectiveBcastRecv]
Process Process-6:
Traceback (most recent call last):
  File "/usr/lib/python3.8/multiprocessing/process.py", line 315, in _bootstrap
    self.run()
  File "/usr/lib/python3.8/multiprocessing/process.py", line 108, in run
    self._target(*self._args, **self._kwargs)
  File "../examples/inference.py", line 211, in proc_func
    embeddings_peek, inputs_peek = inference_with_saved_model(args)
  File "../examples/inference.py", line 101, in inference_with_saved_model
    model = prepare_model(args)
  File "../examples/inference.py", line 80, in prepare_model
    model = DLRMHPS("mean", args["max_vocabulary_size"] // args["gpu_num"], args["embed_vec_size"], args["slot_num"], args["dense_dim"],
  File "/hugectr_dev/study/examples/model_zoo.py", line 145, in __init__
    super(DLRMHPS, self).__init__(**kwargs)
  File "/usr/local/lib/python3.8/dist-packages/tensorflow/python/training/tracking/base.py", line 587, in _method_wrapper
    result = method(self, *args, **kwargs)
  File "/usr/local/lib/python3.8/dist-packages/keras/utils/traceback_utils.py", line 67, in error_handler
    raise e.with_traceback(filtered_tb) from None
  File "/usr/local/lib/python3.8/dist-packages/tensorflow/python/eager/execute.py", line 54, in quick_execute
    tensors = pywrap_tfe.TFE_Py_Execute(ctx._handle, device_name, op_name,
tensorflow.python.framework.errors_impl.DeadlineExceededError: Collective ops is aborted by: Deadline Exceeded
Additional GRPC error information from remote target /job:worker/replica:0/task:0:
:{"created":"@1670813606.460575561","description":"Error received from peer ipv4:127.0.0.1:12340","file":"external/com_github_grpc_grpc/src/core/lib/surface/call.cc","file_line":1056,"grpc_message":"Deadline Exceeded","grpc_status":4}
The error could be from a previous operation. Restart your program to reset. [Op:CollectiveBcastRecv]
Process Process-3:
Traceback (most recent call last):
  File "/usr/lib/python3.8/multiprocessing/process.py", line 315, in _bootstrap
    self.run()
  File "/usr/lib/python3.8/multiprocessing/process.py", line 108, in run
    self._target(*self._args, **self._kwargs)
  File "../examples/inference.py", line 211, in proc_func
    embeddings_peek, inputs_peek = inference_with_saved_model(args)
  File "../examples/inference.py", line 101, in inference_with_saved_model
    model = prepare_model(args)
  File "../examples/inference.py", line 80, in prepare_model
    model = DLRMHPS("mean", args["max_vocabulary_size"] // args["gpu_num"], args["embed_vec_size"], args["slot_num"], args["dense_dim"],
  File "/hugectr_dev/study/examples/model_zoo.py", line 145, in __init__
    super(DLRMHPS, self).__init__(**kwargs)
  File "/usr/local/lib/python3.8/dist-packages/tensorflow/python/training/tracking/base.py", line 587, in _method_wrapper
    result = method(self, *args, **kwargs)
  File "/usr/local/lib/python3.8/dist-packages/keras/utils/traceback_utils.py", line 67, in error_handler
    raise e.with_traceback(filtered_tb) from None
  File "/usr/local/lib/python3.8/dist-packages/tensorflow/python/eager/execute.py", line 54, in quick_execute
    tensors = pywrap_tfe.TFE_Py_Execute(ctx._handle, device_name, op_name,
tensorflow.python.framework.errors_impl.DeadlineExceededError: Collective ops is aborted by: Deadline Exceeded
Additional GRPC error information from remote target /job:worker/replica:0/task:0:
:{"created":"@1670813607.069278401","description":"Error received from peer ipv4:127.0.0.1:12340","file":"external/com_github_grpc_grpc/src/core/lib/surface/call.cc","file_line":1056,"grpc_message":"Deadline Exceeded","grpc_status":4}
The error could be from a previous operation. Restart your program to reset. [Op:CollectiveBcastRecv]
Process Process-5:
Traceback (most recent call last):
  File "/usr/lib/python3.8/multiprocessing/process.py", line 315, in _bootstrap
    self.run()
  File "/usr/lib/python3.8/multiprocessing/process.py", line 108, in run
    self._target(*self._args, **self._kwargs)
  File "../examples/inference.py", line 211, in proc_func
    embeddings_peek, inputs_peek = inference_with_saved_model(args)
  File "../examples/inference.py", line 101, in inference_with_saved_model
    model = prepare_model(args)
  File "../examples/inference.py", line 80, in prepare_model
    model = DLRMHPS("mean", args["max_vocabulary_size"] // args["gpu_num"], args["embed_vec_size"], args["slot_num"], args["dense_dim"],
  File "/hugectr_dev/study/examples/model_zoo.py", line 145, in __init__
    super(DLRMHPS, self).__init__(**kwargs)
  File "/usr/local/lib/python3.8/dist-packages/tensorflow/python/training/tracking/base.py", line 587, in _method_wrapper
    result = method(self, *args, **kwargs)
  File "/usr/local/lib/python3.8/dist-packages/keras/utils/traceback_utils.py", line 67, in error_handler
    raise e.with_traceback(filtered_tb) from None
  File "/usr/local/lib/python3.8/dist-packages/tensorflow/python/eager/execute.py", line 54, in quick_execute
    tensors = pywrap_tfe.TFE_Py_Execute(ctx._handle, device_name, op_name,
tensorflow.python.framework.errors_impl.DeadlineExceededError: Collective ops is aborted by: Deadline Exceeded
Additional GRPC error information from remote target /job:worker/replica:0/task:0:
:{"created":"@1670813606.461386074","description":"Error received from peer ipv4:127.0.0.1:12340","file":"external/com_github_grpc_grpc/src/core/lib/surface/call.cc","file_line":1056,"grpc_message":"Deadline Exceeded","grpc_status":4}
The error could be from a previous operation. Restart your program to reset. [Op:CollectiveBcastRecv]
Process Process-2:
Traceback (most recent call last):
  File "/usr/lib/python3.8/multiprocessing/process.py", line 315, in _bootstrap
    self.run()
  File "/usr/lib/python3.8/multiprocessing/process.py", line 108, in run
    self._target(*self._args, **self._kwargs)
  File "../examples/inference.py", line 211, in proc_func
    embeddings_peek, inputs_peek = inference_with_saved_model(args)
  File "../examples/inference.py", line 101, in inference_with_saved_model
    model = prepare_model(args)
  File "../examples/inference.py", line 80, in prepare_model
    model = DLRMHPS("mean", args["max_vocabulary_size"] // args["gpu_num"], args["embed_vec_size"], args["slot_num"], args["dense_dim"],
  File "/hugectr_dev/study/examples/model_zoo.py", line 145, in __init__
    super(DLRMHPS, self).__init__(**kwargs)
  File "/usr/local/lib/python3.8/dist-packages/tensorflow/python/training/tracking/base.py", line 587, in _method_wrapper
    result = method(self, *args, **kwargs)
  File "/usr/local/lib/python3.8/dist-packages/keras/utils/traceback_utils.py", line 67, in error_handler
    raise e.with_traceback(filtered_tb) from None
  File "/usr/local/lib/python3.8/dist-packages/tensorflow/python/eager/execute.py", line 54, in quick_execute
    tensors = pywrap_tfe.TFE_Py_Execute(ctx._handle, device_name, op_name,
tensorflow.python.framework.errors_impl.DeadlineExceededError: Collective ops is aborted by: Deadline Exceeded
Additional GRPC error information from remote target /job:worker/replica:0/task:0:
:{"created":"@1670813607.010120560","description":"Error received from peer ipv4:127.0.0.1:12340","file":"external/com_github_grpc_grpc/src/core/lib/surface/call.cc","file_line":1056,"grpc_message":"Deadline Exceeded","grpc_status":4}
The error could be from a previous operation. Restart your program to reset. [Op:CollectiveBcastRecv]
Process Process-8:
Traceback (most recent call last):
  File "/usr/lib/python3.8/multiprocessing/process.py", line 315, in _bootstrap
    self.run()
  File "/usr/lib/python3.8/multiprocessing/process.py", line 108, in run
    self._target(*self._args, **self._kwargs)
  File "../examples/inference.py", line 211, in proc_func
    embeddings_peek, inputs_peek = inference_with_saved_model(args)
  File "../examples/inference.py", line 101, in inference_with_saved_model
    model = prepare_model(args)
  File "../examples/inference.py", line 80, in prepare_model
    model = DLRMHPS("mean", args["max_vocabulary_size"] // args["gpu_num"], args["embed_vec_size"], args["slot_num"], args["dense_dim"],
  File "/hugectr_dev/study/examples/model_zoo.py", line 145, in __init__
    super(DLRMHPS, self).__init__(**kwargs)
  File "/usr/local/lib/python3.8/dist-packages/tensorflow/python/training/tracking/base.py", line 587, in _method_wrapper
    result = method(self, *args, **kwargs)
  File "/usr/local/lib/python3.8/dist-packages/keras/utils/traceback_utils.py", line 67, in error_handler
    raise e.with_traceback(filtered_tb) from None
  File "/usr/local/lib/python3.8/dist-packages/tensorflow/python/eager/execute.py", line 54, in quick_execute
    tensors = pywrap_tfe.TFE_Py_Execute(ctx._handle, device_name, op_name,
tensorflow.python.framework.errors_impl.DeadlineExceededError: Collective ops is aborted by: Deadline Exceeded
Additional GRPC error information from remote target /job:worker/replica:0/task:0:
:{"created":"@1670813606.461048186","description":"Error received from peer ipv4:127.0.0.1:12340","file":"external/com_github_grpc_grpc/src/core/lib/surface/call.cc","file_line":1056,"grpc_message":"Deadline Exceeded","grpc_status":4}
The error could be from a previous operation. Restart your program to reset. [Op:CollectiveBcastRecv]
Process Process-1:
Traceback (most recent call last):
  File "/usr/lib/python3.8/multiprocessing/process.py", line 315, in _bootstrap
    self.run()
  File "/usr/lib/python3.8/multiprocessing/process.py", line 108, in run
    self._target(*self._args, **self._kwargs)
  File "../examples/inference.py", line 211, in proc_func
    embeddings_peek, inputs_peek = inference_with_saved_model(args)
  File "../examples/inference.py", line 101, in inference_with_saved_model
    model = prepare_model(args)
  File "../examples/inference.py", line 80, in prepare_model
    model = DLRMHPS("mean", args["max_vocabulary_size"] // args["gpu_num"], args["embed_vec_size"], args["slot_num"], args["dense_dim"],
  File "/hugectr_dev/study/examples/model_zoo.py", line 145, in __init__
    super(DLRMHPS, self).__init__(**kwargs)
  File "/usr/local/lib/python3.8/dist-packages/tensorflow/python/training/tracking/base.py", line 587, in _method_wrapper
    result = method(self, *args, **kwargs)
  File "/usr/local/lib/python3.8/dist-packages/keras/utils/traceback_utils.py", line 67, in error_handler
    raise e.with_traceback(filtered_tb) from None
  File "/usr/local/lib/python3.8/dist-packages/tensorflow/python/eager/execute.py", line 54, in quick_execute
    tensors = pywrap_tfe.TFE_Py_Execute(ctx._handle, device_name, op_name,
tensorflow.python.framework.errors_impl.UnavailableError: Collective ops is aborted by: Task /job:worker/replica:0/task:0 heartbeat timeout. This indicates that the remote task has failed, got preempted, or crashed unexpectedly.
Additional GRPC error information from remote target /job:worker/replica:0/task:0:
:{"created":"@1670813616.310828572","description":"Error received from peer ipv4:127.0.0.1:12340","file":"external/com_github_grpc_grpc/src/core/lib/surface/call.cc","file_line":1056,"grpc_message":"Task /job:worker/replica:0/task:0 heartbeat timeout. This indicates that the remote task has failed, got preempted, or crashed unexpectedly.","grpc_status":14}
The error could be from a previous operation. Restart your program to reset. [Op:CollectiveBcastSend]
