2022-12-12 03:05:51.904792: I tensorflow/core/util/util.cc:169] oneDNN custom operations are on. You may see slightly different numerical results due to floating-point round-off errors from different computation orders. To turn them off, set the environment variable `TF_ENABLE_ONEDNN_OPTS=0`.
2022-12-12 03:05:59.522721: I tensorflow/core/platform/cpu_feature_guard.cc:194] This TensorFlow binary is optimized with oneAPI Deep Neural Network Library (oneDNN) to use the following CPU instructions in performance-critical operations:  SSE3 SSE4.1 SSE4.2 AVX
To enable them in other operations, rebuild TensorFlow with the appropriate compiler flags.
2022-12-12 03:05:59.610727: I tensorflow/core/platform/cpu_feature_guard.cc:194] This TensorFlow binary is optimized with oneAPI Deep Neural Network Library (oneDNN) to use the following CPU instructions in performance-critical operations:  SSE3 SSE4.1 SSE4.2 AVX
To enable them in other operations, rebuild TensorFlow with the appropriate compiler flags.
2022-12-12 03:05:59.665944: I tensorflow/core/platform/cpu_feature_guard.cc:194] This TensorFlow binary is optimized with oneAPI Deep Neural Network Library (oneDNN) to use the following CPU instructions in performance-critical operations:  SSE3 SSE4.1 SSE4.2 AVX
To enable them in other operations, rebuild TensorFlow with the appropriate compiler flags.
2022-12-12 03:05:59.732702: I tensorflow/core/platform/cpu_feature_guard.cc:194] This TensorFlow binary is optimized with oneAPI Deep Neural Network Library (oneDNN) to use the following CPU instructions in performance-critical operations:  SSE3 SSE4.1 SSE4.2 AVX
To enable them in other operations, rebuild TensorFlow with the appropriate compiler flags.
2022-12-12 03:05:59.757155: I tensorflow/core/platform/cpu_feature_guard.cc:194] This TensorFlow binary is optimized with oneAPI Deep Neural Network Library (oneDNN) to use the following CPU instructions in performance-critical operations:  SSE3 SSE4.1 SSE4.2 AVX
To enable them in other operations, rebuild TensorFlow with the appropriate compiler flags.
2022-12-12 03:05:59.791082: I tensorflow/core/platform/cpu_feature_guard.cc:194] This TensorFlow binary is optimized with oneAPI Deep Neural Network Library (oneDNN) to use the following CPU instructions in performance-critical operations:  SSE3 SSE4.1 SSE4.2 AVX
To enable them in other operations, rebuild TensorFlow with the appropriate compiler flags.
2022-12-12 03:05:59.819331: I tensorflow/core/platform/cpu_feature_guard.cc:194] This TensorFlow binary is optimized with oneAPI Deep Neural Network Library (oneDNN) to use the following CPU instructions in performance-critical operations:  SSE3 SSE4.1 SSE4.2 AVX
To enable them in other operations, rebuild TensorFlow with the appropriate compiler flags.
2022-12-12 03:05:59.863456: I tensorflow/core/platform/cpu_feature_guard.cc:194] This TensorFlow binary is optimized with oneAPI Deep Neural Network Library (oneDNN) to use the following CPU instructions in performance-critical operations:  SSE3 SSE4.1 SSE4.2 AVX
To enable them in other operations, rebuild TensorFlow with the appropriate compiler flags.
2022-12-12 03:06:00.750992: W tensorflow/core/common_runtime/gpu/gpu_bfc_allocator.cc:42] Overriding orig_value setting because the TF_FORCE_GPU_ALLOW_GROWTH environment variable is set. Original config value was 0.
2022-12-12 03:06:00.751054: I tensorflow/core/common_runtime/gpu/gpu_device.cc:1532] Created device /job:localhost/replica:0/task:0/device:GPU:0 with 78724 MB memory:  -> device: 1, name: NVIDIA A100-SXM4-80GB, pci bus id: 0000:25:00.0, compute capability: 8.0
2022-12-12 03:06:00.765347: I tensorflow/core/common_runtime/gpu/gpu_device.cc:1532] Created device /job:worker/replica:0/task:1/device:GPU:0 with 78724 MB memory:  -> device: 1, name: NVIDIA A100-SXM4-80GB, pci bus id: 0000:25:00.0, compute capability: 8.0
2022-12-12 03:06:00.786498: I tensorflow/core/distributed_runtime/rpc/grpc_channel.cc:272] Initialize GrpcChannelCache for job worker -> {0 -> localhost:12340, 1 -> localhost:12341, 2 -> localhost:12342, 3 -> localhost:12343, 4 -> localhost:12344, 5 -> localhost:12345, 6 -> localhost:12346, 7 -> localhost:12347}
2022-12-12 03:06:00.786651: I tensorflow/core/distributed_runtime/rpc/grpc_channel.cc:272] Initialize GrpcChannelCache for job worker -> {0 -> localhost:12340, 1 -> localhost:12341, 2 -> localhost:12342, 3 -> localhost:12343, 4 -> localhost:12344, 5 -> localhost:12345, 6 -> localhost:12346, 7 -> localhost:12347}
2022-12-12 03:06:00.797049: I tensorflow/core/distributed_runtime/rpc/grpc_server_lib.cc:438] Started server with target: grpc://localhost:12341
2022-12-12 03:06:00.815467: W tensorflow/core/common_runtime/gpu/gpu_bfc_allocator.cc:42] Overriding orig_value setting because the TF_FORCE_GPU_ALLOW_GROWTH environment variable is set. Original config value was 0.
2022-12-12 03:06:00.815530: I tensorflow/core/common_runtime/gpu/gpu_device.cc:1532] Created device /job:localhost/replica:0/task:0/device:GPU:0 with 78724 MB memory:  -> device: 2, name: NVIDIA A100-SXM4-80GB, pci bus id: 0000:50:00.0, compute capability: 8.0
2022-12-12 03:06:00.828201: W tensorflow/core/common_runtime/gpu/gpu_bfc_allocator.cc:42] Overriding orig_value setting because the TF_FORCE_GPU_ALLOW_GROWTH environment variable is set. Original config value was 0.
2022-12-12 03:06:00.828260: I tensorflow/core/common_runtime/gpu/gpu_device.cc:1532] Created device /job:localhost/replica:0/task:0/device:GPU:0 with 78724 MB memory:  -> device: 0, name: NVIDIA A100-SXM4-80GB, pci bus id: 0000:1f:00.0, compute capability: 8.0
2022-12-12 03:06:00.829598: I tensorflow/core/common_runtime/gpu/gpu_device.cc:1532] Created device /job:worker/replica:0/task:2/device:GPU:0 with 78724 MB memory:  -> device: 2, name: NVIDIA A100-SXM4-80GB, pci bus id: 0000:50:00.0, compute capability: 8.0
2022-12-12 03:06:00.842460: W tensorflow/core/common_runtime/gpu/gpu_bfc_allocator.cc:42] Overriding orig_value setting because the TF_FORCE_GPU_ALLOW_GROWTH environment variable is set. Original config value was 0.
2022-12-12 03:06:00.842517: I tensorflow/core/common_runtime/gpu/gpu_device.cc:1532] Created device /job:localhost/replica:0/task:0/device:GPU:0 with 78724 MB memory:  -> device: 3, name: NVIDIA A100-SXM4-80GB, pci bus id: 0000:55:00.0, compute capability: 8.0
2022-12-12 03:06:00.843732: I tensorflow/core/common_runtime/gpu/gpu_device.cc:1532] Created device /job:worker/replica:0/task:0/device:GPU:0 with 78724 MB memory:  -> device: 0, name: NVIDIA A100-SXM4-80GB, pci bus id: 0000:1f:00.0, compute capability: 8.0
2022-12-12 03:06:00.849943: W tensorflow/core/common_runtime/gpu/gpu_bfc_allocator.cc:42] Overriding orig_value setting because the TF_FORCE_GPU_ALLOW_GROWTH environment variable is set. Original config value was 0.
2022-12-12 03:06:00.849996: I tensorflow/core/common_runtime/gpu/gpu_device.cc:1532] Created device /job:localhost/replica:0/task:0/device:GPU:0 with 78724 MB memory:  -> device: 5, name: NVIDIA A100-SXM4-80GB, pci bus id: 0000:93:00.0, compute capability: 8.0
2022-12-12 03:06:00.850495: W tensorflow/core/common_runtime/gpu/gpu_bfc_allocator.cc:42] Overriding orig_value setting because the TF_FORCE_GPU_ALLOW_GROWTH environment variable is set. Original config value was 0.
2022-12-12 03:06:00.850530: I tensorflow/core/common_runtime/gpu/gpu_device.cc:1532] Created device /job:localhost/replica:0/task:0/device:GPU:0 with 78724 MB memory:  -> device: 7, name: NVIDIA A100-SXM4-80GB, pci bus id: 0000:d0:00.0, compute capability: 8.0
2022-12-12 03:06:00.855810: I tensorflow/core/common_runtime/gpu/gpu_device.cc:1532] Created device /job:worker/replica:0/task:3/device:GPU:0 with 78724 MB memory:  -> device: 3, name: NVIDIA A100-SXM4-80GB, pci bus id: 0000:55:00.0, compute capability: 8.0
2022-12-12 03:06:00.856771: W tensorflow/core/common_runtime/gpu/gpu_bfc_allocator.cc:42] Overriding orig_value setting because the TF_FORCE_GPU_ALLOW_GROWTH environment variable is set. Original config value was 0.
2022-12-12 03:06:00.856817: I tensorflow/core/common_runtime/gpu/gpu_device.cc:1532] Created device /job:localhost/replica:0/task:0/device:GPU:0 with 78724 MB memory:  -> device: 6, name: NVIDIA A100-SXM4-80GB, pci bus id: 0000:ca:00.0, compute capability: 8.0
2022-12-12 03:06:00.863802: I tensorflow/core/distributed_runtime/rpc/grpc_channel.cc:272] Initialize GrpcChannelCache for job worker -> {0 -> localhost:12340, 1 -> localhost:12341, 2 -> localhost:12342, 3 -> localhost:12343, 4 -> localhost:12344, 5 -> localhost:12345, 6 -> localhost:12346, 7 -> localhost:12347}
2022-12-12 03:06:00.863906: I tensorflow/core/distributed_runtime/rpc/grpc_channel.cc:272] Initialize GrpcChannelCache for job worker -> {0 -> localhost:12340, 1 -> localhost:12341, 2 -> localhost:12342, 3 -> localhost:12343, 4 -> localhost:12344, 5 -> localhost:12345, 6 -> localhost:12346, 7 -> localhost:12347}
2022-12-12 03:06:00.863931: I tensorflow/core/common_runtime/gpu/gpu_device.cc:1532] Created device /job:worker/replica:0/task:5/device:GPU:0 with 78724 MB memory:  -> device: 5, name: NVIDIA A100-SXM4-80GB, pci bus id: 0000:93:00.0, compute capability: 8.0
2022-12-12 03:06:00.864646: I tensorflow/core/common_runtime/gpu/gpu_device.cc:1532] Created device /job:worker/replica:0/task:7/device:GPU:0 with 78724 MB memory:  -> device: 7, name: NVIDIA A100-SXM4-80GB, pci bus id: 0000:d0:00.0, compute capability: 8.0
2022-12-12 03:06:00.865047: I tensorflow/core/distributed_runtime/rpc/grpc_server_lib.cc:438] Started server with target: grpc://localhost:12340
2022-12-12 03:06:00.865594: I tensorflow/core/distributed_runtime/rpc/grpc_channel.cc:272] Initialize GrpcChannelCache for job worker -> {0 -> localhost:12340, 1 -> localhost:12341, 2 -> localhost:12342, 3 -> localhost:12343, 4 -> localhost:12344, 5 -> localhost:12345, 6 -> localhost:12346, 7 -> localhost:12347}
2022-12-12 03:06:00.865670: I tensorflow/core/distributed_runtime/rpc/grpc_channel.cc:272] Initialize GrpcChannelCache for job worker -> {0 -> localhost:12340, 1 -> localhost:12341, 2 -> localhost:12342, 3 -> localhost:12343, 4 -> localhost:12344, 5 -> localhost:12345, 6 -> localhost:12346, 7 -> localhost:12347}
2022-12-12 03:06:00.865754: W tensorflow/core/common_runtime/gpu/gpu_bfc_allocator.cc:42] Overriding orig_value setting because the TF_FORCE_GPU_ALLOW_GROWTH environment variable is set. Original config value was 0.
2022-12-12 03:06:00.865792: I tensorflow/core/common_runtime/gpu/gpu_device.cc:1532] Created device /job:localhost/replica:0/task:0/device:GPU:0 with 78724 MB memory:  -> device: 4, name: NVIDIA A100-SXM4-80GB, pci bus id: 0000:8e:00.0, compute capability: 8.0
2022-12-12 03:06:00.866520: I tensorflow/core/distributed_runtime/rpc/grpc_server_lib.cc:438] Started server with target: grpc://localhost:12342
2022-12-12 03:06:00.870619: I tensorflow/core/common_runtime/gpu/gpu_device.cc:1532] Created device /job:worker/replica:0/task:6/device:GPU:0 with 78724 MB memory:  -> device: 6, name: NVIDIA A100-SXM4-80GB, pci bus id: 0000:ca:00.0, compute capability: 8.0
2022-12-12 03:06:00.879369: I tensorflow/core/common_runtime/gpu/gpu_device.cc:1532] Created device /job:worker/replica:0/task:4/device:GPU:0 with 78724 MB memory:  -> device: 4, name: NVIDIA A100-SXM4-80GB, pci bus id: 0000:8e:00.0, compute capability: 8.0
2022-12-12 03:06:00.885548: I tensorflow/core/distributed_runtime/rpc/grpc_channel.cc:272] Initialize GrpcChannelCache for job worker -> {0 -> localhost:12340, 1 -> localhost:12341, 2 -> localhost:12342, 3 -> localhost:12343, 4 -> localhost:12344, 5 -> localhost:12345, 6 -> localhost:12346, 7 -> localhost:12347}
2022-12-12 03:06:00.885655: I tensorflow/core/distributed_runtime/rpc/grpc_channel.cc:272] Initialize GrpcChannelCache for job worker -> {0 -> localhost:12340, 1 -> localhost:12341, 2 -> localhost:12342, 3 -> localhost:12343, 4 -> localhost:12344, 5 -> localhost:12345, 6 -> localhost:12346, 7 -> localhost:12347}
2022-12-12 03:06:00.886552: I tensorflow/core/distributed_runtime/rpc/grpc_channel.cc:272] Initialize GrpcChannelCache for job worker -> {0 -> localhost:12340, 1 -> localhost:12341, 2 -> localhost:12342, 3 -> localhost:12343, 4 -> localhost:12344, 5 -> localhost:12345, 6 -> localhost:12346, 7 -> localhost:12347}
2022-12-12 03:06:00.886639: I tensorflow/core/distributed_runtime/rpc/grpc_channel.cc:272] Initialize GrpcChannelCache for job worker -> {0 -> localhost:12340, 1 -> localhost:12341, 2 -> localhost:12342, 3 -> localhost:12343, 4 -> localhost:12344, 5 -> localhost:12345, 6 -> localhost:12346, 7 -> localhost:12347}
2022-12-12 03:06:00.886786: I tensorflow/core/distributed_runtime/rpc/grpc_server_lib.cc:438] Started server with target: grpc://localhost:12345
2022-12-12 03:06:00.888039: I tensorflow/core/distributed_runtime/rpc/grpc_server_lib.cc:438] Started server with target: grpc://localhost:12347
2022-12-12 03:06:00.892130: I tensorflow/core/distributed_runtime/rpc/grpc_channel.cc:272] Initialize GrpcChannelCache for job worker -> {0 -> localhost:12340, 1 -> localhost:12341, 2 -> localhost:12342, 3 -> localhost:12343, 4 -> localhost:12344, 5 -> localhost:12345, 6 -> localhost:12346, 7 -> localhost:12347}
2022-12-12 03:06:00.892213: I tensorflow/core/distributed_runtime/rpc/grpc_channel.cc:272] Initialize GrpcChannelCache for job worker -> {0 -> localhost:12340, 1 -> localhost:12341, 2 -> localhost:12342, 3 -> localhost:12343, 4 -> localhost:12344, 5 -> localhost:12345, 6 -> localhost:12346, 7 -> localhost:12347}
2022-12-12 03:06:00.893038: I tensorflow/core/distributed_runtime/rpc/grpc_server_lib.cc:438] Started server with target: grpc://localhost:12346
2022-12-12 03:06:00.893417: I tensorflow/core/distributed_runtime/rpc/grpc_channel.cc:272] Initialize GrpcChannelCache for job worker -> {0 -> localhost:12340, 1 -> localhost:12341, 2 -> localhost:12342, 3 -> localhost:12343, 4 -> localhost:12344, 5 -> localhost:12345, 6 -> localhost:12346, 7 -> localhost:12347}
2022-12-12 03:06:00.893493: I tensorflow/core/distributed_runtime/rpc/grpc_channel.cc:272] Initialize GrpcChannelCache for job worker -> {0 -> localhost:12340, 1 -> localhost:12341, 2 -> localhost:12342, 3 -> localhost:12343, 4 -> localhost:12344, 5 -> localhost:12345, 6 -> localhost:12346, 7 -> localhost:12347}
2022-12-12 03:06:00.898331: I tensorflow/core/distributed_runtime/rpc/grpc_server_lib.cc:438] Started server with target: grpc://localhost:12343
2022-12-12 03:06:00.900590: I tensorflow/core/distributed_runtime/rpc/grpc_channel.cc:272] Initialize GrpcChannelCache for job worker -> {0 -> localhost:12340, 1 -> localhost:12341, 2 -> localhost:12342, 3 -> localhost:12343, 4 -> localhost:12344, 5 -> localhost:12345, 6 -> localhost:12346, 7 -> localhost:12347}
2022-12-12 03:06:00.900670: I tensorflow/core/distributed_runtime/rpc/grpc_channel.cc:272] Initialize GrpcChannelCache for job worker -> {0 -> localhost:12340, 1 -> localhost:12341, 2 -> localhost:12342, 3 -> localhost:12343, 4 -> localhost:12344, 5 -> localhost:12345, 6 -> localhost:12346, 7 -> localhost:12347}
2022-12-12 03:06:00.901452: I tensorflow/core/distributed_runtime/rpc/grpc_server_lib.cc:438] Started server with target: grpc://localhost:12344
[HCTR][03:06:02.949][ERROR][RK0][main]: using mock embedding with 882774585 * 128 elements
[HCTR][03:06:02.949][ERROR][RK0][main]: using mock embedding with 882774585 * 128 elements
[HCTR][03:06:02.949][ERROR][RK0][main]: using mock embedding with 882774585 * 128 elements
[HCTR][03:06:02.950][ERROR][RK0][main]: using mock embedding with 882774585 * 128 elements
[HCTR][03:06:02.956][ERROR][RK0][main]: using mock embedding with 882774585 * 128 elements
[HCTR][03:06:02.957][ERROR][RK0][main]: using mock embedding with 882774585 * 128 elements
[HCTR][03:06:03.001][ERROR][RK0][main]: using mock embedding with 882774585 * 128 elements
[HCTR][03:06:03.001][ERROR][RK0][main]: using mock embedding with 882774585 * 128 elements
2022-12-12 03:06:10.882219: E tensorflow/core/common_runtime/base_collective_executor.cc:249] BaseCollectiveExecutor::StartAbort DEADLINE_EXCEEDED: Deadline Exceeded
Additional GRPC error information from remote target /job:worker/replica:0/task:0:
:{"created":"@1670814370.882083669","description":"Error received from peer ipv4:127.0.0.1:12340","file":"external/com_github_grpc_grpc/src/core/lib/surface/call.cc","file_line":1056,"grpc_message":"Deadline Exceeded","grpc_status":4}
2022-12-12 03:06:10.889534: E tensorflow/core/common_runtime/base_collective_executor.cc:249] BaseCollectiveExecutor::StartAbort DEADLINE_EXCEEDED: Deadline Exceeded
Additional GRPC error information from remote target /job:worker/replica:0/task:0:
:{"created":"@1670814370.889368057","description":"Error received from peer ipv4:127.0.0.1:12340","file":"external/com_github_grpc_grpc/src/core/lib/surface/call.cc","file_line":1056,"grpc_message":"Deadline Exceeded","grpc_status":4}
2022-12-12 03:06:10.890166: E tensorflow/core/common_runtime/base_collective_executor.cc:249] BaseCollectiveExecutor::StartAbort DEADLINE_EXCEEDED: Deadline Exceeded
Additional GRPC error information from remote target /job:worker/replica:0/task:0:
:{"created":"@1670814370.890070150","description":"Error received from peer ipv4:127.0.0.1:12340","file":"external/com_github_grpc_grpc/src/core/lib/surface/call.cc","file_line":1056,"grpc_message":"Deadline Exceeded","grpc_status":4}
2022-12-12 03:06:10.898133: E tensorflow/core/common_runtime/base_collective_executor.cc:249] BaseCollectiveExecutor::StartAbort DEADLINE_EXCEEDED: Deadline Exceeded
Additional GRPC error information from remote target /job:worker/replica:0/task:0:
:{"created":"@1670814370.898026262","description":"Error received from peer ipv4:127.0.0.1:12340","file":"external/com_github_grpc_grpc/src/core/lib/surface/call.cc","file_line":1056,"grpc_message":"Deadline Exceeded","grpc_status":4}
2022-12-12 03:06:10.900353: E tensorflow/core/common_runtime/base_collective_executor.cc:249] BaseCollectiveExecutor::StartAbort DEADLINE_EXCEEDED: Deadline Exceeded
Additional GRPC error information from remote target /job:worker/replica:0/task:0:
:{"created":"@1670814370.900269635","description":"Error received from peer ipv4:127.0.0.1:12340","file":"external/com_github_grpc_grpc/src/core/lib/surface/call.cc","file_line":1056,"grpc_message":"Deadline Exceeded","grpc_status":4}
2022-12-12 03:06:10.903967: E tensorflow/core/common_runtime/base_collective_executor.cc:249] BaseCollectiveExecutor::StartAbort DEADLINE_EXCEEDED: Deadline Exceeded
Additional GRPC error information from remote target /job:worker/replica:0/task:0:
:{"created":"@1670814370.903853674","description":"Error received from peer ipv4:127.0.0.1:12340","file":"external/com_github_grpc_grpc/src/core/lib/surface/call.cc","file_line":1056,"grpc_message":"Deadline Exceeded","grpc_status":4}
2022-12-12 03:06:11.798968: E tensorflow/core/common_runtime/base_collective_executor.cc:249] BaseCollectiveExecutor::StartAbort DEADLINE_EXCEEDED: Deadline Exceeded
Additional GRPC error information from remote target /job:worker/replica:0/task:0:
:{"created":"@1670814371.798848489","description":"Error received from peer ipv4:127.0.0.1:12340","file":"external/com_github_grpc_grpc/src/core/lib/surface/call.cc","file_line":1056,"grpc_message":"Deadline Exceeded","grpc_status":4}
2022-12-12 03:06:21.125253: E tensorflow/core/common_runtime/base_collective_executor.cc:249] BaseCollectiveExecutor::StartAbort UNAVAILABLE: Task /job:worker/replica:0/task:0 heartbeat timeout. This indicates that the remote task has failed, got preempted, or crashed unexpectedly.
Additional GRPC error information from remote target /job:worker/replica:0/task:0:
:{"created":"@1670814381.125012601","description":"Error received from peer ipv4:127.0.0.1:12340","file":"external/com_github_grpc_grpc/src/core/lib/surface/call.cc","file_line":1056,"grpc_message":"Task /job:worker/replica:0/task:0 heartbeat timeout. This indicates that the remote task has failed, got preempted, or crashed unexpectedly.","grpc_status":14} [type.googleapis.com/tensorflow.CoordinationServiceError='']
Process Process-2:
Traceback (most recent call last):
  File "/usr/lib/python3.8/multiprocessing/process.py", line 315, in _bootstrap
    self.run()
  File "/usr/lib/python3.8/multiprocessing/process.py", line 108, in run
    self._target(*self._args, **self._kwargs)
  File "../examples/inference.py", line 211, in proc_func
    embeddings_peek, inputs_peek = inference_with_saved_model(args)
  File "../examples/inference.py", line 101, in inference_with_saved_model
    model = prepare_model(args)
  File "../examples/inference.py", line 68, in prepare_model
    model = DCNHPS(args["embed_vec_size"], args["slot_num"], args["dense_dim"])
  File "/hugectr_dev/study/examples/tfrs_dcn.py", line 240, in __init__
    super().__init__()
  File "/usr/local/lib/python3.8/dist-packages/tensorflow/python/training/tracking/base.py", line 587, in _method_wrapper
    result = method(self, *args, **kwargs)
  File "/usr/local/lib/python3.8/dist-packages/keras/utils/traceback_utils.py", line 67, in error_handler
    raise e.with_traceback(filtered_tb) from None
  File "/usr/local/lib/python3.8/dist-packages/tensorflow/python/eager/execute.py", line 54, in quick_execute
    tensors = pywrap_tfe.TFE_Py_Execute(ctx._handle, device_name, op_name,
tensorflow.python.framework.errors_impl.DeadlineExceededError: Collective ops is aborted by: Deadline Exceeded
Additional GRPC error information from remote target /job:worker/replica:0/task:0:
:{"created":"@1670814371.798848489","description":"Error received from peer ipv4:127.0.0.1:12340","file":"external/com_github_grpc_grpc/src/core/lib/surface/call.cc","file_line":1056,"grpc_message":"Deadline Exceeded","grpc_status":4}
The error could be from a previous operation. Restart your program to reset. [Op:CollectiveBcastRecv]
Process Process-4:
Traceback (most recent call last):
  File "/usr/lib/python3.8/multiprocessing/process.py", line 315, in _bootstrap
    self.run()
  File "/usr/lib/python3.8/multiprocessing/process.py", line 108, in run
    self._target(*self._args, **self._kwargs)
  File "../examples/inference.py", line 211, in proc_func
    embeddings_peek, inputs_peek = inference_with_saved_model(args)
  File "../examples/inference.py", line 101, in inference_with_saved_model
    model = prepare_model(args)
  File "../examples/inference.py", line 68, in prepare_model
    model = DCNHPS(args["embed_vec_size"], args["slot_num"], args["dense_dim"])
  File "/hugectr_dev/study/examples/tfrs_dcn.py", line 240, in __init__
    super().__init__()
  File "/usr/local/lib/python3.8/dist-packages/tensorflow/python/training/tracking/base.py", line 587, in _method_wrapper
    result = method(self, *args, **kwargs)
  File "/usr/local/lib/python3.8/dist-packages/keras/utils/traceback_utils.py", line 67, in error_handler
    raise e.with_traceback(filtered_tb) from None
  File "/usr/local/lib/python3.8/dist-packages/tensorflow/python/eager/execute.py", line 54, in quick_execute
    tensors = pywrap_tfe.TFE_Py_Execute(ctx._handle, device_name, op_name,
tensorflow.python.framework.errors_impl.DeadlineExceededError: Collective ops is aborted by: Deadline Exceeded
Additional GRPC error information from remote target /job:worker/replica:0/task:0:
:{"created":"@1670814370.900269635","description":"Error received from peer ipv4:127.0.0.1:12340","file":"external/com_github_grpc_grpc/src/core/lib/surface/call.cc","file_line":1056,"grpc_message":"Deadline Exceeded","grpc_status":4}
The error could be from a previous operation. Restart your program to reset. [Op:CollectiveBcastRecv]
Process Process-7:
Traceback (most recent call last):
  File "/usr/lib/python3.8/multiprocessing/process.py", line 315, in _bootstrap
    self.run()
  File "/usr/lib/python3.8/multiprocessing/process.py", line 108, in run
    self._target(*self._args, **self._kwargs)
  File "../examples/inference.py", line 211, in proc_func
    embeddings_peek, inputs_peek = inference_with_saved_model(args)
  File "../examples/inference.py", line 101, in inference_with_saved_model
    model = prepare_model(args)
  File "../examples/inference.py", line 68, in prepare_model
    model = DCNHPS(args["embed_vec_size"], args["slot_num"], args["dense_dim"])
  File "/hugectr_dev/study/examples/tfrs_dcn.py", line 240, in __init__
    super().__init__()
  File "/usr/local/lib/python3.8/dist-packages/tensorflow/python/training/tracking/base.py", line 587, in _method_wrapper
    result = method(self, *args, **kwargs)
  File "/usr/local/lib/python3.8/dist-packages/keras/utils/traceback_utils.py", line 67, in error_handler
    raise e.with_traceback(filtered_tb) from None
  File "/usr/local/lib/python3.8/dist-packages/tensorflow/python/eager/execute.py", line 54, in quick_execute
    tensors = pywrap_tfe.TFE_Py_Execute(ctx._handle, device_name, op_name,
tensorflow.python.framework.errors_impl.DeadlineExceededError: Collective ops is aborted by: Deadline Exceeded
Additional GRPC error information from remote target /job:worker/replica:0/task:0:
:{"created":"@1670814370.898026262","description":"Error received from peer ipv4:127.0.0.1:12340","file":"external/com_github_grpc_grpc/src/core/lib/surface/call.cc","file_line":1056,"grpc_message":"Deadline Exceeded","grpc_status":4}
The error could be from a previous operation. Restart your program to reset. [Op:CollectiveBcastRecv]
Process Process-8:
Traceback (most recent call last):
  File "/usr/lib/python3.8/multiprocessing/process.py", line 315, in _bootstrap
    self.run()
  File "/usr/lib/python3.8/multiprocessing/process.py", line 108, in run
    self._target(*self._args, **self._kwargs)
  File "../examples/inference.py", line 211, in proc_func
    embeddings_peek, inputs_peek = inference_with_saved_model(args)
  File "../examples/inference.py", line 101, in inference_with_saved_model
    model = prepare_model(args)
  File "../examples/inference.py", line 68, in prepare_model
    model = DCNHPS(args["embed_vec_size"], args["slot_num"], args["dense_dim"])
  File "/hugectr_dev/study/examples/tfrs_dcn.py", line 240, in __init__
    super().__init__()
  File "/usr/local/lib/python3.8/dist-packages/tensorflow/python/training/tracking/base.py", line 587, in _method_wrapper
    result = method(self, *args, **kwargs)
  File "/usr/local/lib/python3.8/dist-packages/keras/utils/traceback_utils.py", line 67, in error_handler
    raise e.with_traceback(filtered_tb) from None
  File "/usr/local/lib/python3.8/dist-packages/tensorflow/python/eager/execute.py", line 54, in quick_execute
    tensors = pywrap_tfe.TFE_Py_Execute(ctx._handle, device_name, op_name,
tensorflow.python.framework.errors_impl.DeadlineExceededError: Collective ops is aborted by: Deadline Exceeded
Additional GRPC error information from remote target /job:worker/replica:0/task:0:
:{"created":"@1670814370.890070150","description":"Error received from peer ipv4:127.0.0.1:12340","file":"external/com_github_grpc_grpc/src/core/lib/surface/call.cc","file_line":1056,"grpc_message":"Deadline Exceeded","grpc_status":4}
The error could be from a previous operation. Restart your program to reset. [Op:CollectiveBcastRecv]
Process Process-6:
Traceback (most recent call last):
  File "/usr/lib/python3.8/multiprocessing/process.py", line 315, in _bootstrap
    self.run()
  File "/usr/lib/python3.8/multiprocessing/process.py", line 108, in run
    self._target(*self._args, **self._kwargs)
  File "../examples/inference.py", line 211, in proc_func
    embeddings_peek, inputs_peek = inference_with_saved_model(args)
  File "../examples/inference.py", line 101, in inference_with_saved_model
    model = prepare_model(args)
  File "../examples/inference.py", line 68, in prepare_model
    model = DCNHPS(args["embed_vec_size"], args["slot_num"], args["dense_dim"])
  File "/hugectr_dev/study/examples/tfrs_dcn.py", line 240, in __init__
    super().__init__()
  File "/usr/local/lib/python3.8/dist-packages/tensorflow/python/training/tracking/base.py", line 587, in _method_wrapper
    result = method(self, *args, **kwargs)
  File "/usr/local/lib/python3.8/dist-packages/keras/utils/traceback_utils.py", line 67, in error_handler
    raise e.with_traceback(filtered_tb) from None
  File "/usr/local/lib/python3.8/dist-packages/tensorflow/python/eager/execute.py", line 54, in quick_execute
    tensors = pywrap_tfe.TFE_Py_Execute(ctx._handle, device_name, op_name,
tensorflow.python.framework.errors_impl.DeadlineExceededError: Collective ops is aborted by: Deadline Exceeded
Additional GRPC error information from remote target /job:worker/replica:0/task:0:
:{"created":"@1670814370.889368057","description":"Error received from peer ipv4:127.0.0.1:12340","file":"external/com_github_grpc_grpc/src/core/lib/surface/call.cc","file_line":1056,"grpc_message":"Deadline Exceeded","grpc_status":4}
The error could be from a previous operation. Restart your program to reset. [Op:CollectiveBcastRecv]
Process Process-3:
Traceback (most recent call last):
  File "/usr/lib/python3.8/multiprocessing/process.py", line 315, in _bootstrap
    self.run()
  File "/usr/lib/python3.8/multiprocessing/process.py", line 108, in run
    self._target(*self._args, **self._kwargs)
  File "../examples/inference.py", line 211, in proc_func
    embeddings_peek, inputs_peek = inference_with_saved_model(args)
  File "../examples/inference.py", line 101, in inference_with_saved_model
    model = prepare_model(args)
  File "../examples/inference.py", line 68, in prepare_model
    model = DCNHPS(args["embed_vec_size"], args["slot_num"], args["dense_dim"])
  File "/hugectr_dev/study/examples/tfrs_dcn.py", line 240, in __init__
    super().__init__()
  File "/usr/local/lib/python3.8/dist-packages/tensorflow/python/training/tracking/base.py", line 587, in _method_wrapper
    result = method(self, *args, **kwargs)
  File "/usr/local/lib/python3.8/dist-packages/keras/utils/traceback_utils.py", line 67, in error_handler
    raise e.with_traceback(filtered_tb) from None
  File "/usr/local/lib/python3.8/dist-packages/tensorflow/python/eager/execute.py", line 54, in quick_execute
    tensors = pywrap_tfe.TFE_Py_Execute(ctx._handle, device_name, op_name,
tensorflow.python.framework.errors_impl.DeadlineExceededError: Collective ops is aborted by: Deadline Exceeded
Additional GRPC error information from remote target /job:worker/replica:0/task:0:
:{"created":"@1670814370.882083669","description":"Error received from peer ipv4:127.0.0.1:12340","file":"external/com_github_grpc_grpc/src/core/lib/surface/call.cc","file_line":1056,"grpc_message":"Deadline Exceeded","grpc_status":4}
The error could be from a previous operation. Restart your program to reset. [Op:CollectiveBcastRecv]
Process Process-5:
Traceback (most recent call last):
  File "/usr/lib/python3.8/multiprocessing/process.py", line 315, in _bootstrap
    self.run()
  File "/usr/lib/python3.8/multiprocessing/process.py", line 108, in run
    self._target(*self._args, **self._kwargs)
  File "../examples/inference.py", line 211, in proc_func
    embeddings_peek, inputs_peek = inference_with_saved_model(args)
  File "../examples/inference.py", line 101, in inference_with_saved_model
    model = prepare_model(args)
  File "../examples/inference.py", line 68, in prepare_model
    model = DCNHPS(args["embed_vec_size"], args["slot_num"], args["dense_dim"])
  File "/hugectr_dev/study/examples/tfrs_dcn.py", line 240, in __init__
    super().__init__()
  File "/usr/local/lib/python3.8/dist-packages/tensorflow/python/training/tracking/base.py", line 587, in _method_wrapper
    result = method(self, *args, **kwargs)
  File "/usr/local/lib/python3.8/dist-packages/keras/utils/traceback_utils.py", line 67, in error_handler
    raise e.with_traceback(filtered_tb) from None
  File "/usr/local/lib/python3.8/dist-packages/tensorflow/python/eager/execute.py", line 54, in quick_execute
    tensors = pywrap_tfe.TFE_Py_Execute(ctx._handle, device_name, op_name,
tensorflow.python.framework.errors_impl.DeadlineExceededError: Collective ops is aborted by: Deadline Exceeded
Additional GRPC error information from remote target /job:worker/replica:0/task:0:
:{"created":"@1670814370.903853674","description":"Error received from peer ipv4:127.0.0.1:12340","file":"external/com_github_grpc_grpc/src/core/lib/surface/call.cc","file_line":1056,"grpc_message":"Deadline Exceeded","grpc_status":4}
The error could be from a previous operation. Restart your program to reset. [Op:CollectiveBcastRecv]
Process Process-1:
Traceback (most recent call last):
  File "/usr/lib/python3.8/multiprocessing/process.py", line 315, in _bootstrap
    self.run()
  File "/usr/lib/python3.8/multiprocessing/process.py", line 108, in run
    self._target(*self._args, **self._kwargs)
  File "../examples/inference.py", line 211, in proc_func
    embeddings_peek, inputs_peek = inference_with_saved_model(args)
  File "../examples/inference.py", line 101, in inference_with_saved_model
    model = prepare_model(args)
  File "../examples/inference.py", line 68, in prepare_model
    model = DCNHPS(args["embed_vec_size"], args["slot_num"], args["dense_dim"])
  File "/hugectr_dev/study/examples/tfrs_dcn.py", line 240, in __init__
    super().__init__()
  File "/usr/local/lib/python3.8/dist-packages/tensorflow/python/training/tracking/base.py", line 587, in _method_wrapper
    result = method(self, *args, **kwargs)
  File "/usr/local/lib/python3.8/dist-packages/keras/utils/traceback_utils.py", line 67, in error_handler
    raise e.with_traceback(filtered_tb) from None
  File "/usr/local/lib/python3.8/dist-packages/tensorflow/python/eager/execute.py", line 54, in quick_execute
    tensors = pywrap_tfe.TFE_Py_Execute(ctx._handle, device_name, op_name,
tensorflow.python.framework.errors_impl.UnavailableError: Collective ops is aborted by: Task /job:worker/replica:0/task:0 heartbeat timeout. This indicates that the remote task has failed, got preempted, or crashed unexpectedly.
Additional GRPC error information from remote target /job:worker/replica:0/task:0:
:{"created":"@1670814381.125012601","description":"Error received from peer ipv4:127.0.0.1:12340","file":"external/com_github_grpc_grpc/src/core/lib/surface/call.cc","file_line":1056,"grpc_message":"Task /job:worker/replica:0/task:0 heartbeat timeout. This indicates that the remote task has failed, got preempted, or crashed unexpectedly.","grpc_status":14}
The error could be from a previous operation. Restart your program to reset. [Op:CollectiveBcastSend]
