2022-12-12 03:04:50.615723: I tensorflow/core/util/util.cc:169] oneDNN custom operations are on. You may see slightly different numerical results due to floating-point round-off errors from different computation orders. To turn them off, set the environment variable `TF_ENABLE_ONEDNN_OPTS=0`.
2022-12-12 03:04:58.284780: I tensorflow/core/platform/cpu_feature_guard.cc:194] This TensorFlow binary is optimized with oneAPI Deep Neural Network Library (oneDNN) to use the following CPU instructions in performance-critical operations:  SSE3 SSE4.1 SSE4.2 AVX
To enable them in other operations, rebuild TensorFlow with the appropriate compiler flags.
2022-12-12 03:04:58.432477: I tensorflow/core/platform/cpu_feature_guard.cc:194] This TensorFlow binary is optimized with oneAPI Deep Neural Network Library (oneDNN) to use the following CPU instructions in performance-critical operations:  SSE3 SSE4.1 SSE4.2 AVX
To enable them in other operations, rebuild TensorFlow with the appropriate compiler flags.
2022-12-12 03:04:58.450389: I tensorflow/core/platform/cpu_feature_guard.cc:194] This TensorFlow binary is optimized with oneAPI Deep Neural Network Library (oneDNN) to use the following CPU instructions in performance-critical operations:  SSE3 SSE4.1 SSE4.2 AVX
To enable them in other operations, rebuild TensorFlow with the appropriate compiler flags.
2022-12-12 03:04:58.458881: I tensorflow/core/platform/cpu_feature_guard.cc:194] This TensorFlow binary is optimized with oneAPI Deep Neural Network Library (oneDNN) to use the following CPU instructions in performance-critical operations:  SSE3 SSE4.1 SSE4.2 AVX
To enable them in other operations, rebuild TensorFlow with the appropriate compiler flags.
2022-12-12 03:04:58.481238: I tensorflow/core/platform/cpu_feature_guard.cc:194] This TensorFlow binary is optimized with oneAPI Deep Neural Network Library (oneDNN) to use the following CPU instructions in performance-critical operations:  SSE3 SSE4.1 SSE4.2 AVX
To enable them in other operations, rebuild TensorFlow with the appropriate compiler flags.
2022-12-12 03:04:58.515509: I tensorflow/core/platform/cpu_feature_guard.cc:194] This TensorFlow binary is optimized with oneAPI Deep Neural Network Library (oneDNN) to use the following CPU instructions in performance-critical operations:  SSE3 SSE4.1 SSE4.2 AVX
To enable them in other operations, rebuild TensorFlow with the appropriate compiler flags.
2022-12-12 03:04:58.553127: I tensorflow/core/platform/cpu_feature_guard.cc:194] This TensorFlow binary is optimized with oneAPI Deep Neural Network Library (oneDNN) to use the following CPU instructions in performance-critical operations:  SSE3 SSE4.1 SSE4.2 AVX
To enable them in other operations, rebuild TensorFlow with the appropriate compiler flags.
2022-12-12 03:04:58.587695: I tensorflow/core/platform/cpu_feature_guard.cc:194] This TensorFlow binary is optimized with oneAPI Deep Neural Network Library (oneDNN) to use the following CPU instructions in performance-critical operations:  SSE3 SSE4.1 SSE4.2 AVX
To enable them in other operations, rebuild TensorFlow with the appropriate compiler flags.
2022-12-12 03:04:59.499639: W tensorflow/core/common_runtime/gpu/gpu_bfc_allocator.cc:42] Overriding orig_value setting because the TF_FORCE_GPU_ALLOW_GROWTH environment variable is set. Original config value was 0.
2022-12-12 03:04:59.499704: I tensorflow/core/common_runtime/gpu/gpu_device.cc:1532] Created device /job:localhost/replica:0/task:0/device:GPU:0 with 78724 MB memory:  -> device: 1, name: NVIDIA A100-SXM4-80GB, pci bus id: 0000:25:00.0, compute capability: 8.0
2022-12-12 03:04:59.513392: I tensorflow/core/common_runtime/gpu/gpu_device.cc:1532] Created device /job:worker/replica:0/task:1/device:GPU:0 with 78724 MB memory:  -> device: 1, name: NVIDIA A100-SXM4-80GB, pci bus id: 0000:25:00.0, compute capability: 8.0
2022-12-12 03:04:59.535131: I tensorflow/core/distributed_runtime/rpc/grpc_channel.cc:272] Initialize GrpcChannelCache for job worker -> {0 -> localhost:12340, 1 -> localhost:12341, 2 -> localhost:12342, 3 -> localhost:12343, 4 -> localhost:12344, 5 -> localhost:12345, 6 -> localhost:12346, 7 -> localhost:12347}
2022-12-12 03:04:59.535278: I tensorflow/core/distributed_runtime/rpc/grpc_channel.cc:272] Initialize GrpcChannelCache for job worker -> {0 -> localhost:12340, 1 -> localhost:12341, 2 -> localhost:12342, 3 -> localhost:12343, 4 -> localhost:12344, 5 -> localhost:12345, 6 -> localhost:12346, 7 -> localhost:12347}
2022-12-12 03:04:59.550990: I tensorflow/core/distributed_runtime/rpc/grpc_server_lib.cc:438] Started server with target: grpc://localhost:12341
2022-12-12 03:04:59.580483: W tensorflow/core/common_runtime/gpu/gpu_bfc_allocator.cc:42] Overriding orig_value setting because the TF_FORCE_GPU_ALLOW_GROWTH environment variable is set. Original config value was 0.
2022-12-12 03:04:59.580551: I tensorflow/core/common_runtime/gpu/gpu_device.cc:1532] Created device /job:localhost/replica:0/task:0/device:GPU:0 with 78724 MB memory:  -> device: 2, name: NVIDIA A100-SXM4-80GB, pci bus id: 0000:50:00.0, compute capability: 8.0
2022-12-12 03:04:59.581020: W tensorflow/core/common_runtime/gpu/gpu_bfc_allocator.cc:42] Overriding orig_value setting because the TF_FORCE_GPU_ALLOW_GROWTH environment variable is set. Original config value was 0.
2022-12-12 03:04:59.581063: I tensorflow/core/common_runtime/gpu/gpu_device.cc:1532] Created device /job:localhost/replica:0/task:0/device:GPU:0 with 78724 MB memory:  -> device: 0, name: NVIDIA A100-SXM4-80GB, pci bus id: 0000:1f:00.0, compute capability: 8.0
2022-12-12 03:04:59.588043: W tensorflow/core/common_runtime/gpu/gpu_bfc_allocator.cc:42] Overriding orig_value setting because the TF_FORCE_GPU_ALLOW_GROWTH environment variable is set. Original config value was 0.
2022-12-12 03:04:59.588108: I tensorflow/core/common_runtime/gpu/gpu_device.cc:1532] Created device /job:localhost/replica:0/task:0/device:GPU:0 with 78724 MB memory:  -> device: 7, name: NVIDIA A100-SXM4-80GB, pci bus id: 0000:d0:00.0, compute capability: 8.0
2022-12-12 03:04:59.589716: W tensorflow/core/common_runtime/gpu/gpu_bfc_allocator.cc:42] Overriding orig_value setting because the TF_FORCE_GPU_ALLOW_GROWTH environment variable is set. Original config value was 0.
2022-12-12 03:04:59.589763: I tensorflow/core/common_runtime/gpu/gpu_device.cc:1532] Created device /job:localhost/replica:0/task:0/device:GPU:0 with 78724 MB memory:  -> device: 6, name: NVIDIA A100-SXM4-80GB, pci bus id: 0000:ca:00.0, compute capability: 8.0
2022-12-12 03:04:59.595306: I tensorflow/core/common_runtime/gpu/gpu_device.cc:1532] Created device /job:worker/replica:0/task:2/device:GPU:0 with 78724 MB memory:  -> device: 2, name: NVIDIA A100-SXM4-80GB, pci bus id: 0000:50:00.0, compute capability: 8.0
2022-12-12 03:04:59.595733: I tensorflow/core/common_runtime/gpu/gpu_device.cc:1532] Created device /job:worker/replica:0/task:0/device:GPU:0 with 78724 MB memory:  -> device: 0, name: NVIDIA A100-SXM4-80GB, pci bus id: 0000:1f:00.0, compute capability: 8.0
2022-12-12 03:04:59.600451: W tensorflow/core/common_runtime/gpu/gpu_bfc_allocator.cc:42] Overriding orig_value setting because the TF_FORCE_GPU_ALLOW_GROWTH environment variable is set. Original config value was 0.
2022-12-12 03:04:59.600494: I tensorflow/core/common_runtime/gpu/gpu_device.cc:1532] Created device /job:localhost/replica:0/task:0/device:GPU:0 with 78724 MB memory:  -> device: 5, name: NVIDIA A100-SXM4-80GB, pci bus id: 0000:93:00.0, compute capability: 8.0
2022-12-12 03:04:59.601904: W tensorflow/core/common_runtime/gpu/gpu_bfc_allocator.cc:42] Overriding orig_value setting because the TF_FORCE_GPU_ALLOW_GROWTH environment variable is set. Original config value was 0.
2022-12-12 03:04:59.601945: I tensorflow/core/common_runtime/gpu/gpu_device.cc:1532] Created device /job:localhost/replica:0/task:0/device:GPU:0 with 78724 MB memory:  -> device: 3, name: NVIDIA A100-SXM4-80GB, pci bus id: 0000:55:00.0, compute capability: 8.0
2022-12-12 03:04:59.603241: I tensorflow/core/common_runtime/gpu/gpu_device.cc:1532] Created device /job:worker/replica:0/task:7/device:GPU:0 with 78724 MB memory:  -> device: 7, name: NVIDIA A100-SXM4-80GB, pci bus id: 0000:d0:00.0, compute capability: 8.0
2022-12-12 03:04:59.604708: I tensorflow/core/common_runtime/gpu/gpu_device.cc:1532] Created device /job:worker/replica:0/task:6/device:GPU:0 with 78724 MB memory:  -> device: 6, name: NVIDIA A100-SXM4-80GB, pci bus id: 0000:ca:00.0, compute capability: 8.0
2022-12-12 03:04:59.615167: I tensorflow/core/common_runtime/gpu/gpu_device.cc:1532] Created device /job:worker/replica:0/task:5/device:GPU:0 with 78724 MB memory:  -> device: 5, name: NVIDIA A100-SXM4-80GB, pci bus id: 0000:93:00.0, compute capability: 8.0
2022-12-12 03:04:59.616095: I tensorflow/core/distributed_runtime/rpc/grpc_channel.cc:272] Initialize GrpcChannelCache for job worker -> {0 -> localhost:12340, 1 -> localhost:12341, 2 -> localhost:12342, 3 -> localhost:12343, 4 -> localhost:12344, 5 -> localhost:12345, 6 -> localhost:12346, 7 -> localhost:12347}
2022-12-12 03:04:59.616188: I tensorflow/core/distributed_runtime/rpc/grpc_channel.cc:272] Initialize GrpcChannelCache for job worker -> {0 -> localhost:12340, 1 -> localhost:12341, 2 -> localhost:12342, 3 -> localhost:12343, 4 -> localhost:12344, 5 -> localhost:12345, 6 -> localhost:12346, 7 -> localhost:12347}
2022-12-12 03:04:59.616241: I tensorflow/core/common_runtime/gpu/gpu_device.cc:1532] Created device /job:worker/replica:0/task:3/device:GPU:0 with 78724 MB memory:  -> device: 3, name: NVIDIA A100-SXM4-80GB, pci bus id: 0000:55:00.0, compute capability: 8.0
2022-12-12 03:04:59.617260: I tensorflow/core/distributed_runtime/rpc/grpc_server_lib.cc:438] Started server with target: grpc://localhost:12340
2022-12-12 03:04:59.624416: I tensorflow/core/distributed_runtime/rpc/grpc_channel.cc:272] Initialize GrpcChannelCache for job worker -> {0 -> localhost:12340, 1 -> localhost:12341, 2 -> localhost:12342, 3 -> localhost:12343, 4 -> localhost:12344, 5 -> localhost:12345, 6 -> localhost:12346, 7 -> localhost:12347}
2022-12-12 03:04:59.624523: I tensorflow/core/distributed_runtime/rpc/grpc_channel.cc:272] Initialize GrpcChannelCache for job worker -> {0 -> localhost:12340, 1 -> localhost:12341, 2 -> localhost:12342, 3 -> localhost:12343, 4 -> localhost:12344, 5 -> localhost:12345, 6 -> localhost:12346, 7 -> localhost:12347}
2022-12-12 03:04:59.625423: I tensorflow/core/distributed_runtime/rpc/grpc_channel.cc:272] Initialize GrpcChannelCache for job worker -> {0 -> localhost:12340, 1 -> localhost:12341, 2 -> localhost:12342, 3 -> localhost:12343, 4 -> localhost:12344, 5 -> localhost:12345, 6 -> localhost:12346, 7 -> localhost:12347}
2022-12-12 03:04:59.625451: I tensorflow/core/distributed_runtime/rpc/grpc_server_lib.cc:438] Started server with target: grpc://localhost:12347
2022-12-12 03:04:59.625497: I tensorflow/core/distributed_runtime/rpc/grpc_channel.cc:272] Initialize GrpcChannelCache for job worker -> {0 -> localhost:12340, 1 -> localhost:12341, 2 -> localhost:12342, 3 -> localhost:12343, 4 -> localhost:12344, 5 -> localhost:12345, 6 -> localhost:12346, 7 -> localhost:12347}
2022-12-12 03:04:59.626313: I tensorflow/core/distributed_runtime/rpc/grpc_server_lib.cc:438] Started server with target: grpc://localhost:12346
2022-12-12 03:04:59.628012: W tensorflow/core/common_runtime/gpu/gpu_bfc_allocator.cc:42] Overriding orig_value setting because the TF_FORCE_GPU_ALLOW_GROWTH environment variable is set. Original config value was 0.
2022-12-12 03:04:59.628055: I tensorflow/core/common_runtime/gpu/gpu_device.cc:1532] Created device /job:localhost/replica:0/task:0/device:GPU:0 with 78724 MB memory:  -> device: 4, name: NVIDIA A100-SXM4-80GB, pci bus id: 0000:8e:00.0, compute capability: 8.0
2022-12-12 03:04:59.636973: I tensorflow/core/distributed_runtime/rpc/grpc_channel.cc:272] Initialize GrpcChannelCache for job worker -> {0 -> localhost:12340, 1 -> localhost:12341, 2 -> localhost:12342, 3 -> localhost:12343, 4 -> localhost:12344, 5 -> localhost:12345, 6 -> localhost:12346, 7 -> localhost:12347}
2022-12-12 03:04:59.637101: I tensorflow/core/distributed_runtime/rpc/grpc_channel.cc:272] Initialize GrpcChannelCache for job worker -> {0 -> localhost:12340, 1 -> localhost:12341, 2 -> localhost:12342, 3 -> localhost:12343, 4 -> localhost:12344, 5 -> localhost:12345, 6 -> localhost:12346, 7 -> localhost:12347}
2022-12-12 03:04:59.638289: I tensorflow/core/distributed_runtime/rpc/grpc_server_lib.cc:438] Started server with target: grpc://localhost:12345
2022-12-12 03:04:59.642539: I tensorflow/core/common_runtime/gpu/gpu_device.cc:1532] Created device /job:worker/replica:0/task:4/device:GPU:0 with 78724 MB memory:  -> device: 4, name: NVIDIA A100-SXM4-80GB, pci bus id: 0000:8e:00.0, compute capability: 8.0
2022-12-12 03:04:59.644580: I tensorflow/core/distributed_runtime/rpc/grpc_channel.cc:272] Initialize GrpcChannelCache for job worker -> {0 -> localhost:12340, 1 -> localhost:12341, 2 -> localhost:12342, 3 -> localhost:12343, 4 -> localhost:12344, 5 -> localhost:12345, 6 -> localhost:12346, 7 -> localhost:12347}
2022-12-12 03:04:59.644660: I tensorflow/core/distributed_runtime/rpc/grpc_channel.cc:272] Initialize GrpcChannelCache for job worker -> {0 -> localhost:12340, 1 -> localhost:12341, 2 -> localhost:12342, 3 -> localhost:12343, 4 -> localhost:12344, 5 -> localhost:12345, 6 -> localhost:12346, 7 -> localhost:12347}
2022-12-12 03:04:59.646245: I tensorflow/core/distributed_runtime/rpc/grpc_server_lib.cc:438] Started server with target: grpc://localhost:12342
2022-12-12 03:04:59.657085: I tensorflow/core/distributed_runtime/rpc/grpc_channel.cc:272] Initialize GrpcChannelCache for job worker -> {0 -> localhost:12340, 1 -> localhost:12341, 2 -> localhost:12342, 3 -> localhost:12343, 4 -> localhost:12344, 5 -> localhost:12345, 6 -> localhost:12346, 7 -> localhost:12347}
2022-12-12 03:04:59.657178: I tensorflow/core/distributed_runtime/rpc/grpc_channel.cc:272] Initialize GrpcChannelCache for job worker -> {0 -> localhost:12340, 1 -> localhost:12341, 2 -> localhost:12342, 3 -> localhost:12343, 4 -> localhost:12344, 5 -> localhost:12345, 6 -> localhost:12346, 7 -> localhost:12347}
2022-12-12 03:04:59.658011: I tensorflow/core/distributed_runtime/rpc/grpc_server_lib.cc:438] Started server with target: grpc://localhost:12343
2022-12-12 03:04:59.663495: I tensorflow/core/distributed_runtime/rpc/grpc_channel.cc:272] Initialize GrpcChannelCache for job worker -> {0 -> localhost:12340, 1 -> localhost:12341, 2 -> localhost:12342, 3 -> localhost:12343, 4 -> localhost:12344, 5 -> localhost:12345, 6 -> localhost:12346, 7 -> localhost:12347}
2022-12-12 03:04:59.663579: I tensorflow/core/distributed_runtime/rpc/grpc_channel.cc:272] Initialize GrpcChannelCache for job worker -> {0 -> localhost:12340, 1 -> localhost:12341, 2 -> localhost:12342, 3 -> localhost:12343, 4 -> localhost:12344, 5 -> localhost:12345, 6 -> localhost:12346, 7 -> localhost:12347}
2022-12-12 03:04:59.664364: I tensorflow/core/distributed_runtime/rpc/grpc_server_lib.cc:438] Started server with target: grpc://localhost:12344
[HCTR][03:05:01.705][ERROR][RK0][main]: using mock embedding with 882774585 * 128 elements
[HCTR][03:05:01.705][ERROR][RK0][main]: using mock embedding with 882774585 * 128 elements
[HCTR][03:05:01.713][ERROR][RK0][main]: using mock embedding with 882774585 * 128 elements
[HCTR][03:05:01.715][ERROR][RK0][main]: using mock embedding with 882774585 * 128 elements
[HCTR][03:05:01.715][ERROR][RK0][main]: using mock embedding with 882774585 * 128 elements
[HCTR][03:05:01.717][ERROR][RK0][main]: using mock embedding with 882774585 * 128 elements
[HCTR][03:05:01.719][ERROR][RK0][main]: using mock embedding with 882774585 * 128 elements
[HCTR][03:05:01.731][ERROR][RK0][main]: using mock embedding with 882774585 * 128 elements
2022-12-12 03:05:09.633807: E tensorflow/core/common_runtime/base_collective_executor.cc:249] BaseCollectiveExecutor::StartAbort DEADLINE_EXCEEDED: Deadline Exceeded
Additional GRPC error information from remote target /job:worker/replica:0/task:0:
:{"created":"@1670814309.633671650","description":"Error received from peer ipv4:127.0.0.1:12340","file":"external/com_github_grpc_grpc/src/core/lib/surface/call.cc","file_line":1056,"grpc_message":"Deadline Exceeded","grpc_status":4}
2022-12-12 03:05:19.635187: E tensorflow/core/common_runtime/base_collective_executor.cc:249] BaseCollectiveExecutor::StartAbort DEADLINE_EXCEEDED: Deadline Exceeded
Additional GRPC error information from remote target /job:worker/replica:0/task:0:
:{"created":"@1670814319.635098350","description":"Error received from peer ipv4:127.0.0.1:12340","file":"external/com_github_grpc_grpc/src/core/lib/surface/call.cc","file_line":1056,"grpc_message":"Deadline Exceeded","grpc_status":4}
2022-12-12 03:05:19.640694: E tensorflow/core/common_runtime/base_collective_executor.cc:249] BaseCollectiveExecutor::StartAbort DEADLINE_EXCEEDED: Deadline Exceeded
Additional GRPC error information from remote target /job:worker/replica:0/task:0:
:{"created":"@1670814319.640591664","description":"Error received from peer ipv4:127.0.0.1:12340","file":"external/com_github_grpc_grpc/src/core/lib/surface/call.cc","file_line":1056,"grpc_message":"Deadline Exceeded","grpc_status":4}
2022-12-12 03:05:19.648830: E tensorflow/core/common_runtime/base_collective_executor.cc:249] BaseCollectiveExecutor::StartAbort DEADLINE_EXCEEDED: Deadline Exceeded
Additional GRPC error information from remote target /job:worker/replica:0/task:0:
:{"created":"@1670814319.648756606","description":"Error received from peer ipv4:127.0.0.1:12340","file":"external/com_github_grpc_grpc/src/core/lib/surface/call.cc","file_line":1056,"grpc_message":"Deadline Exceeded","grpc_status":4}
2022-12-12 03:05:19.659683: E tensorflow/core/common_runtime/base_collective_executor.cc:249] BaseCollectiveExecutor::StartAbort DEADLINE_EXCEEDED: Deadline Exceeded
Additional GRPC error information from remote target /job:worker/replica:0/task:0:
:{"created":"@1670814319.659617552","description":"Error received from peer ipv4:127.0.0.1:12340","file":"external/com_github_grpc_grpc/src/core/lib/surface/call.cc","file_line":1056,"grpc_message":"Deadline Exceeded","grpc_status":4}
2022-12-12 03:05:19.667056: E tensorflow/core/common_runtime/base_collective_executor.cc:249] BaseCollectiveExecutor::StartAbort DEADLINE_EXCEEDED: Deadline Exceeded
Additional GRPC error information from remote target /job:worker/replica:0/task:0:
:{"created":"@1670814319.666980684","description":"Error received from peer ipv4:127.0.0.1:12340","file":"external/com_github_grpc_grpc/src/core/lib/surface/call.cc","file_line":1056,"grpc_message":"Deadline Exceeded","grpc_status":4}
2022-12-12 03:05:19.722140: E tensorflow/core/common_runtime/base_collective_executor.cc:249] BaseCollectiveExecutor::StartAbort UNAVAILABLE: Error reported from /job:worker/task:0: Task /job:worker/replica:0/task:0 heartbeat timeout. This indicates that the remote task has failed, got preempted, or crashed unexpectedly. [type.googleapis.com/tensorflow.CoordinationServiceError='\"\x08\n\x06worker']
2022-12-12 03:05:19.726364: E tensorflow/core/common_runtime/base_collective_executor.cc:249] BaseCollectiveExecutor::StartAbort UNAVAILABLE: Task /job:worker/replica:0/task:0 heartbeat timeout. This indicates that the remote task has failed, got preempted, or crashed unexpectedly.
Additional GRPC error information from remote target /job:worker/replica:0/task:0:
:{"created":"@1670814319.726240342","description":"Error received from peer ipv4:127.0.0.1:12340","file":"external/com_github_grpc_grpc/src/core/lib/surface/call.cc","file_line":1056,"grpc_message":"Task /job:worker/replica:0/task:0 heartbeat timeout. This indicates that the remote task has failed, got preempted, or crashed unexpectedly.","grpc_status":14} [type.googleapis.com/tensorflow.CoordinationServiceError='']
Process Process-4:
Traceback (most recent call last):
  File "/usr/lib/python3.8/multiprocessing/process.py", line 315, in _bootstrap
    self.run()
  File "/usr/lib/python3.8/multiprocessing/process.py", line 108, in run
    self._target(*self._args, **self._kwargs)
  File "../examples/inference.py", line 211, in proc_func
    embeddings_peek, inputs_peek = inference_with_saved_model(args)
  File "../examples/inference.py", line 101, in inference_with_saved_model
    model = prepare_model(args)
  File "../examples/inference.py", line 68, in prepare_model
    model = DCNHPS(args["embed_vec_size"], args["slot_num"], args["dense_dim"])
  File "/hugectr_dev/study/examples/tfrs_dcn.py", line 240, in __init__
    super().__init__()
  File "/usr/local/lib/python3.8/dist-packages/tensorflow/python/training/tracking/base.py", line 587, in _method_wrapper
    result = method(self, *args, **kwargs)
  File "/usr/local/lib/python3.8/dist-packages/keras/utils/traceback_utils.py", line 67, in error_handler
    raise e.with_traceback(filtered_tb) from None
  File "/usr/local/lib/python3.8/dist-packages/tensorflow/python/eager/execute.py", line 54, in quick_execute
    tensors = pywrap_tfe.TFE_Py_Execute(ctx._handle, device_name, op_name,
tensorflow.python.framework.errors_impl.DeadlineExceededError: Collective ops is aborted by: Deadline Exceeded
Additional GRPC error information from remote target /job:worker/replica:0/task:0:
:{"created":"@1670814319.659617552","description":"Error received from peer ipv4:127.0.0.1:12340","file":"external/com_github_grpc_grpc/src/core/lib/surface/call.cc","file_line":1056,"grpc_message":"Deadline Exceeded","grpc_status":4}
The error could be from a previous operation. Restart your program to reset. [Op:CollectiveBcastRecv]
Process Process-3:
Traceback (most recent call last):
  File "/usr/lib/python3.8/multiprocessing/process.py", line 315, in _bootstrap
    self.run()
  File "/usr/lib/python3.8/multiprocessing/process.py", line 108, in run
    self._target(*self._args, **self._kwargs)
  File "../examples/inference.py", line 211, in proc_func
    embeddings_peek, inputs_peek = inference_with_saved_model(args)
  File "../examples/inference.py", line 101, in inference_with_saved_model
    model = prepare_model(args)
  File "../examples/inference.py", line 68, in prepare_model
    model = DCNHPS(args["embed_vec_size"], args["slot_num"], args["dense_dim"])
  File "/hugectr_dev/study/examples/tfrs_dcn.py", line 240, in __init__
    super().__init__()
  File "/usr/local/lib/python3.8/dist-packages/tensorflow/python/training/tracking/base.py", line 587, in _method_wrapper
    result = method(self, *args, **kwargs)
  File "/usr/local/lib/python3.8/dist-packages/keras/utils/traceback_utils.py", line 67, in error_handler
    raise e.with_traceback(filtered_tb) from None
  File "/usr/local/lib/python3.8/dist-packages/tensorflow/python/eager/execute.py", line 54, in quick_execute
    tensors = pywrap_tfe.TFE_Py_Execute(ctx._handle, device_name, op_name,
tensorflow.python.framework.errors_impl.DeadlineExceededError: Collective ops is aborted by: Deadline Exceeded
Additional GRPC error information from remote target /job:worker/replica:0/task:0:
:{"created":"@1670814319.648756606","description":"Error received from peer ipv4:127.0.0.1:12340","file":"external/com_github_grpc_grpc/src/core/lib/surface/call.cc","file_line":1056,"grpc_message":"Deadline Exceeded","grpc_status":4}
The error could be from a previous operation. Restart your program to reset. [Op:CollectiveBcastRecv]
Process Process-7:
Traceback (most recent call last):
  File "/usr/lib/python3.8/multiprocessing/process.py", line 315, in _bootstrap
    self.run()
  File "/usr/lib/python3.8/multiprocessing/process.py", line 108, in run
    self._target(*self._args, **self._kwargs)
  File "../examples/inference.py", line 211, in proc_func
    embeddings_peek, inputs_peek = inference_with_saved_model(args)
  File "../examples/inference.py", line 101, in inference_with_saved_model
    model = prepare_model(args)
  File "../examples/inference.py", line 68, in prepare_model
    model = DCNHPS(args["embed_vec_size"], args["slot_num"], args["dense_dim"])
  File "/hugectr_dev/study/examples/tfrs_dcn.py", line 240, in __init__
    super().__init__()
  File "/usr/local/lib/python3.8/dist-packages/tensorflow/python/training/tracking/base.py", line 587, in _method_wrapper
    result = method(self, *args, **kwargs)
  File "/usr/local/lib/python3.8/dist-packages/keras/utils/traceback_utils.py", line 67, in error_handler
    raise e.with_traceback(filtered_tb) from None
  File "/usr/local/lib/python3.8/dist-packages/tensorflow/python/eager/execute.py", line 54, in quick_execute
    tensors = pywrap_tfe.TFE_Py_Execute(ctx._handle, device_name, op_name,
tensorflow.python.framework.errors_impl.DeadlineExceededError: Collective ops is aborted by: Deadline Exceeded
Additional GRPC error information from remote target /job:worker/replica:0/task:0:
:{"created":"@1670814319.635098350","description":"Error received from peer ipv4:127.0.0.1:12340","file":"external/com_github_grpc_grpc/src/core/lib/surface/call.cc","file_line":1056,"grpc_message":"Deadline Exceeded","grpc_status":4}
The error could be from a previous operation. Restart your program to reset. [Op:CollectiveBcastRecv]
Process Process-2:
Traceback (most recent call last):
  File "/usr/lib/python3.8/multiprocessing/process.py", line 315, in _bootstrap
    self.run()
  File "/usr/lib/python3.8/multiprocessing/process.py", line 108, in run
    self._target(*self._args, **self._kwargs)
  File "../examples/inference.py", line 211, in proc_func
    embeddings_peek, inputs_peek = inference_with_saved_model(args)
  File "../examples/inference.py", line 101, in inference_with_saved_model
    model = prepare_model(args)
  File "../examples/inference.py", line 68, in prepare_model
    model = DCNHPS(args["embed_vec_size"], args["slot_num"], args["dense_dim"])
  File "/hugectr_dev/study/examples/tfrs_dcn.py", line 240, in __init__
    super().__init__()
  File "/usr/local/lib/python3.8/dist-packages/tensorflow/python/training/tracking/base.py", line 587, in _method_wrapper
    result = method(self, *args, **kwargs)
  File "/usr/local/lib/python3.8/dist-packages/keras/utils/traceback_utils.py", line 67, in error_handler
    raise e.with_traceback(filtered_tb) from None
  File "/usr/local/lib/python3.8/dist-packages/tensorflow/python/eager/execute.py", line 54, in quick_execute
    tensors = pywrap_tfe.TFE_Py_Execute(ctx._handle, device_name, op_name,
tensorflow.python.framework.errors_impl.UnavailableError: Collective ops is aborted by: Error reported from /job:worker/task:0: Task /job:worker/replica:0/task:0 heartbeat timeout. This indicates that the remote task has failed, got preempted, or crashed unexpectedly.
The error could be from a previous operation. Restart your program to reset. [Op:CollectiveBcastRecv]
Process Process-6:
Traceback (most recent call last):
  File "/usr/lib/python3.8/multiprocessing/process.py", line 315, in _bootstrap
    self.run()
  File "/usr/lib/python3.8/multiprocessing/process.py", line 108, in run
    self._target(*self._args, **self._kwargs)
  File "../examples/inference.py", line 211, in proc_func
    embeddings_peek, inputs_peek = inference_with_saved_model(args)
  File "../examples/inference.py", line 101, in inference_with_saved_model
    model = prepare_model(args)
  File "../examples/inference.py", line 68, in prepare_model
    model = DCNHPS(args["embed_vec_size"], args["slot_num"], args["dense_dim"])
  File "/hugectr_dev/study/examples/tfrs_dcn.py", line 240, in __init__
    super().__init__()
  File "/usr/local/lib/python3.8/dist-packages/tensorflow/python/training/tracking/base.py", line 587, in _method_wrapper
    result = method(self, *args, **kwargs)
  File "/usr/local/lib/python3.8/dist-packages/keras/utils/traceback_utils.py", line 67, in error_handler
    raise e.with_traceback(filtered_tb) from None
  File "/usr/local/lib/python3.8/dist-packages/tensorflow/python/eager/execute.py", line 54, in quick_execute
    tensors = pywrap_tfe.TFE_Py_Execute(ctx._handle, device_name, op_name,
tensorflow.python.framework.errors_impl.DeadlineExceededError: Collective ops is aborted by: Deadline Exceeded
Additional GRPC error information from remote target /job:worker/replica:0/task:0:
:{"created":"@1670814319.640591664","description":"Error received from peer ipv4:127.0.0.1:12340","file":"external/com_github_grpc_grpc/src/core/lib/surface/call.cc","file_line":1056,"grpc_message":"Deadline Exceeded","grpc_status":4}
The error could be from a previous operation. Restart your program to reset. [Op:CollectiveBcastRecv]
Process Process-8:
Traceback (most recent call last):
  File "/usr/lib/python3.8/multiprocessing/process.py", line 315, in _bootstrap
    self.run()
  File "/usr/lib/python3.8/multiprocessing/process.py", line 108, in run
    self._target(*self._args, **self._kwargs)
  File "../examples/inference.py", line 211, in proc_func
    embeddings_peek, inputs_peek = inference_with_saved_model(args)
  File "../examples/inference.py", line 101, in inference_with_saved_model
    model = prepare_model(args)
  File "../examples/inference.py", line 68, in prepare_model
    model = DCNHPS(args["embed_vec_size"], args["slot_num"], args["dense_dim"])
  File "/hugectr_dev/study/examples/tfrs_dcn.py", line 240, in __init__
    super().__init__()
  File "/usr/local/lib/python3.8/dist-packages/tensorflow/python/training/tracking/base.py", line 587, in _method_wrapper
    result = method(self, *args, **kwargs)
  File "/usr/local/lib/python3.8/dist-packages/keras/utils/traceback_utils.py", line 67, in error_handler
    raise e.with_traceback(filtered_tb) from None
  File "/usr/local/lib/python3.8/dist-packages/tensorflow/python/eager/execute.py", line 54, in quick_execute
    tensors = pywrap_tfe.TFE_Py_Execute(ctx._handle, device_name, op_name,
tensorflow.python.framework.errors_impl.DeadlineExceededError: Collective ops is aborted by: Deadline Exceeded
Additional GRPC error information from remote target /job:worker/replica:0/task:0:
:{"created":"@1670814309.633671650","description":"Error received from peer ipv4:127.0.0.1:12340","file":"external/com_github_grpc_grpc/src/core/lib/surface/call.cc","file_line":1056,"grpc_message":"Deadline Exceeded","grpc_status":4}
The error could be from a previous operation. Restart your program to reset. [Op:CollectiveBcastRecv]
Process Process-5:
Traceback (most recent call last):
  File "/usr/lib/python3.8/multiprocessing/process.py", line 315, in _bootstrap
    self.run()
  File "/usr/lib/python3.8/multiprocessing/process.py", line 108, in run
    self._target(*self._args, **self._kwargs)
  File "../examples/inference.py", line 211, in proc_func
    embeddings_peek, inputs_peek = inference_with_saved_model(args)
  File "../examples/inference.py", line 101, in inference_with_saved_model
    model = prepare_model(args)
  File "../examples/inference.py", line 68, in prepare_model
    model = DCNHPS(args["embed_vec_size"], args["slot_num"], args["dense_dim"])
  File "/hugectr_dev/study/examples/tfrs_dcn.py", line 240, in __init__
    super().__init__()
  File "/usr/local/lib/python3.8/dist-packages/tensorflow/python/training/tracking/base.py", line 587, in _method_wrapper
    result = method(self, *args, **kwargs)
  File "/usr/local/lib/python3.8/dist-packages/keras/utils/traceback_utils.py", line 67, in error_handler
    raise e.with_traceback(filtered_tb) from None
  File "/usr/local/lib/python3.8/dist-packages/tensorflow/python/eager/execute.py", line 54, in quick_execute
    tensors = pywrap_tfe.TFE_Py_Execute(ctx._handle, device_name, op_name,
tensorflow.python.framework.errors_impl.DeadlineExceededError: Collective ops is aborted by: Deadline Exceeded
Additional GRPC error information from remote target /job:worker/replica:0/task:0:
:{"created":"@1670814319.666980684","description":"Error received from peer ipv4:127.0.0.1:12340","file":"external/com_github_grpc_grpc/src/core/lib/surface/call.cc","file_line":1056,"grpc_message":"Deadline Exceeded","grpc_status":4}
The error could be from a previous operation. Restart your program to reset. [Op:CollectiveBcastRecv]
Process Process-1:
Traceback (most recent call last):
  File "/usr/lib/python3.8/multiprocessing/process.py", line 315, in _bootstrap
    self.run()
  File "/usr/lib/python3.8/multiprocessing/process.py", line 108, in run
    self._target(*self._args, **self._kwargs)
  File "../examples/inference.py", line 211, in proc_func
    embeddings_peek, inputs_peek = inference_with_saved_model(args)
  File "../examples/inference.py", line 101, in inference_with_saved_model
    model = prepare_model(args)
  File "../examples/inference.py", line 68, in prepare_model
    model = DCNHPS(args["embed_vec_size"], args["slot_num"], args["dense_dim"])
  File "/hugectr_dev/study/examples/tfrs_dcn.py", line 240, in __init__
    super().__init__()
  File "/usr/local/lib/python3.8/dist-packages/tensorflow/python/training/tracking/base.py", line 587, in _method_wrapper
    result = method(self, *args, **kwargs)
  File "/usr/local/lib/python3.8/dist-packages/keras/utils/traceback_utils.py", line 67, in error_handler
    raise e.with_traceback(filtered_tb) from None
  File "/usr/local/lib/python3.8/dist-packages/tensorflow/python/eager/execute.py", line 54, in quick_execute
    tensors = pywrap_tfe.TFE_Py_Execute(ctx._handle, device_name, op_name,
tensorflow.python.framework.errors_impl.UnavailableError: Collective ops is aborted by: Task /job:worker/replica:0/task:0 heartbeat timeout. This indicates that the remote task has failed, got preempted, or crashed unexpectedly.
Additional GRPC error information from remote target /job:worker/replica:0/task:0:
:{"created":"@1670814319.726240342","description":"Error received from peer ipv4:127.0.0.1:12340","file":"external/com_github_grpc_grpc/src/core/lib/surface/call.cc","file_line":1056,"grpc_message":"Task /job:worker/replica:0/task:0 heartbeat timeout. This indicates that the remote task has failed, got preempted, or crashed unexpectedly.","grpc_status":14}
The error could be from a previous operation. Restart your program to reset. [Op:CollectiveBcastSend]
